Workbook
Name UPDATE: 'Data Sheet'!$E$1

Sheet Financials>
B2: ="Historical Financial Statements - "&'Data Sheet'!B1 -> Historical Financial Statements - BAJAJ AUTO LTD
B3: Years | C3: ='Data Sheet'!B16 -> 42460 | D3: ='Data Sheet'!C16 -> 42825 | E3: ='Data Sheet'!D16 -> 43190 | F3: ='Data Sheet'!E16 -> 43555 | G3: ='Data Sheet'!F16 -> 43921 | H3: ='Data Sheet'!G16 -> 44286 | I3: ='Data Sheet'!H16 -> 44651 | J3: ='Data Sheet'!I16 -> 45016 | ... L3: ='Data Sheet'!K16 -> 45747 | M3: LTM
A4: # | B4: Income Statement
B5: Sales | C5: =IFERROR('Data Sheet'!B17,0) -> 22573.69 | D5: =IFERROR('Data Sheet'!C17,0) -> 21754.72 | E5: =IFERROR('Data Sheet'!D17,0) -> 25209.93 | F5: =IFERROR('Data Sheet'!E17,0) -> 30357.63 | G5: =IFERROR('Data Sheet'!F17,0) -> 29918.65 | H5: =IFERROR('Data Sheet'!G17,0) -> 27741.08 | I5: =IFERROR('Data Sheet'!H17,0) -> 33144.71 | J5: =IFERROR('Data Sheet'!I17,0) -> 36455.38 | ... L5: =IFERROR('Data Sheet'!K17,0) -> 50994.55 | M5: =IFERROR(SUM('Data Sheet'!H42:K42),0) -> 57718.86
B6: Sales Growth | C6: - | D6: =D5/C5-1 -> -0.036279846 | E6: =E5/D5-1 -> 0.15882576 | F6: =F5/E5-1 -> 0.20419335 | G6: =G5/F5-1 -> -0.014460286 | H6: =H5/G5-1 -> -0.07278303 | I6: =I5/H5-1 -> 0.19478802 | J6: =J5/I5-1 -> 0.099885321 | K6: =K5/J5-1 -> 0.2308315 | ... M6: =M5/L5-1 -> 0.13186331
B8: COGS | C8: =IFERROR(SUM('Data Sheet'!B18,'Data Sheet'!B20:B22)-1*'Data Sheet'!B19,0) -> 16741.72 | D8: =IFERROR(SUM('Data Sheet'!C18,'Data Sheet'!C20:C22)-1*'Data Sheet'!C19,0) -> 16267.98 | E8: =IFERROR(SUM('Data Sheet'!D18,'Data Sheet'!D20:D22)-1*'Data Sheet'!D19,0) -> 19133.1 | F8: =IFERROR(SUM('Data Sheet'!E18,'Data Sheet'!E20:E22)-1*'Data Sheet'!E19,0) -> 23807 | G8: =IFERROR(SUM('Data Sheet'!F18,'Data Sheet'!F20:F22)-1*'Data Sheet'!F19,0) -> 23218.68 | H8: =IFERROR(SUM('Data Sheet'!G18,'Data Sheet'!G20:G22)-1*'Data Sheet'!G19,0) -> 21594.17 | I8: =IFERROR(SUM('Data Sheet'!H18,'Data Sheet'!H20:H22)-1*'Data Sheet'!H19,0) -> 26640.11 | J8: =IFERROR(SUM('Data Sheet'!I18,'Data Sheet'!I20:I22)-1*'Data Sheet'!I19,0) -> 28475.5 | ... L8: =IFERROR(SUM('Data Sheet'!K18,'Data Sheet'!K20:K22)-1*'Data Sheet'!K19,0) -> 38182.02 | M8: =IFERROR(SUM('Data Sheet'!H43:K43),0) -> 46009.73
B9: COGS % Sales | C9: =C8/C5-1 -> -0.25835253 | D9: =D8/D5-1 -> -0.25220918 | E9: =E8/E5-1 -> -0.24104906 | F9: =F8/F5-1 -> -0.215782 | G9: =G8/G5-1 -> -0.22393958 | H9: =H8/H5-1 -> -0.2215815 | I9: =I8/I5-1 -> -0.19624851 | J9: =J8/J5-1 -> -0.21889444 | ... L9: =L8/L5-1 -> -0.25125293 | M9: -
B11: Gross Margin | C11: =C5-C8 -> 5831.97 | D11: =D5-D8 -> 5486.74 | E11: =E5-E8 -> 6076.83 | F11: =F5-F8 -> 6550.63 | G11: =G5-G8 -> 6699.97 | H11: =H5-H8 -> 6146.91 | I11: =I5-I8 -> 6504.6 | J11: =J5-J8 -> 7979.88 | ... M11: =M5-M8 -> 11709.13
B12: Gross Margin % Sales | C12: =C11/C5 -> 0.25835253 | D12: =D11/D5 -> 0.25220918 | E12: =E11/E5 -> 0.24104906 | F12: =F11/F5 -> 0.215782 | G12: =G11/G5 -> 0.22393958 | H12: =H11/H5 -> 0.2215815 | I12: =I11/I5 -> 0.19624851 | J12: =J11/J5 -> 0.21889444 | ... M12: =M11/M5 -> 0.20286489
B14: Selling And General Expenses | C14: =IFERROR(SUM('Data Sheet'!B23:B24),0) -> 1039.02 | D14: =IFERROR(SUM('Data Sheet'!C23:C24),0) -> 1058.11 | E14: =IFERROR(SUM('Data Sheet'!D23:D24),0) -> 1231.03 | F14: =IFERROR(SUM('Data Sheet'!E23:E24),0) -> 1352.71 | G14: =IFERROR(SUM('Data Sheet'!F23:F24),0) -> 1590.63 | H14: =IFERROR(SUM('Data Sheet'!G23:G24),0) -> 1209.13 | I14: =IFERROR(SUM('Data Sheet'!H23:H24),0) -> 1245.8 | J14: =IFERROR(SUM('Data Sheet'!I23:I24),0) -> 1515.24 | ... M14: =IFERROR(SUM('Data Sheet'!L23:L24),0) -> 0
B15: S&G Exp % | C15: =C14/C5 -> 0.04602792 | D15: =D14/D5 -> 0.048638181 | E15: =E14/E5 -> 0.048831155 | F15: =F14/F5 -> 0.044559144 | G15: =G14/G5 -> 0.053165166 | H15: =H14/H5 -> 0.043586263 | I15: =I14/I5 -> 0.037586692 | J15: =J14/J5 -> 0.041564236 | ... M15: =M14/M5 -> 0
B17: EBITDA | C17: =C11-C14 -> 4792.95 | D17: =D11-D14 -> 4428.63 | E17: =E11-E14 -> 4845.8 | F17: =F11-F14 -> 5197.92 | G17: =G11-G14 -> 5109.34 | H17: =H11-H14 -> 4937.78 | I17: =I11-I14 -> 5258.8 | J17: =J11-J14 -> 6464.64 | ... M17: =M11-M14 -> 11709.13
B18: EBITDA % Sales | C18: =C17/C5 -> 0.21232461 | D18: =D17/D5 -> 0.203571 | E18: =E17/E5 -> 0.19221791 | F18: =F17/F5 -> 0.17122285 | G18: =G17/G5 -> 0.17077442 | H18: =H17/H5 -> 0.17799523 | I18: =I17/I5 -> 0.15866182 | J18: =J17/J5 -> 0.1773302 | ... M18: =M17/M5 -> 0.20286489
B20: Intrest | C20: =IFERROR(SUM('Data Sheet'!B27),0) -> 1.05 | D20: =IFERROR(SUM('Data Sheet'!C27),0) -> 1.4 | E20: =IFERROR(SUM('Data Sheet'!D27),0) -> 1.31 | F20: =IFERROR(SUM('Data Sheet'!E27),0) -> 4.48 | G20: =IFERROR(SUM('Data Sheet'!F27),0) -> 3.16 | H20: =IFERROR(SUM('Data Sheet'!G27),0) -> 6.66 | I20: =IFERROR(SUM('Data Sheet'!H27),0) -> 8.66 | J20: =IFERROR(SUM('Data Sheet'!I27),0) -> 39.51 | ... M20: =IFERROR(SUM('Data Sheet'!L27),0) -> 0
B21: Intrest % Sales | C21: =C20/C5 -> 4.6514327e-05 | D21: =D20/D5 -> 6.4353851e-05 | E21: =E20/E5 -> 5.1963651e-05 | F21: =F20/F5 -> 0.0001475741 | G21: =G20/G5 -> 0.00010561974 | H21: =H20/H5 -> 0.00024007717 | I21: =I20/I5 -> 0.0002612785 | J21: =J20/J5 -> 0.0010837907 | ... M21: =M20/M5 -> 0
B23: Depreciation | C23: =IFERROR('Data Sheet'!B26,0) -> 307.16 | D23: =IFERROR(SUM('Data Sheet'!C26),0) -> 307.29 | E23: =IFERROR(SUM('Data Sheet'!D26),0) -> 314.8 | F23: =IFERROR(SUM('Data Sheet'!E26),0) -> 265.69 | G23: =IFERROR(SUM('Data Sheet'!F26),0) -> 246.43 | H23: =IFERROR(SUM('Data Sheet'!G26),0) -> 259.37 | I23: =IFERROR(SUM('Data Sheet'!H26),0) -> 269.76 | J23: =IFERROR(SUM('Data Sheet'!I26),0) -> 285.85 | K23: =IFERROR(SUM('Data Sheet'!J26),0) -> 364.77 | ... M23: =IFERROR(SUM('Data Sheet'!L26),0) -> 0
B24: Depreciation % Sales | C24: =C23/C5 -> 0.013606991 | D24: =D23/D5 -> 0.014125211 | E24: =E23/E5 -> 0.012487143 | F24: =F23/F5 -> 0.0087520007 | G24: =G23/G5 -> 0.0082366684 | H24: =H23/H5 -> 0.009349672 | I24: =I23/I5 -> 0.0081388553 | J24: =J23/J5 -> 0.0078410923 | ... M24: =M23/M5 -> 0
B26: Earning Before Tax | C26: =C17-(C20+C23) -> 4484.74 | D26: =D17-(D20+D23) -> 4119.94 | E26: =E17-(E20+E23) -> 4529.69 | F26: =F17-(F20+F23) -> 4927.75 | G26: =G17-(G20+G23) -> 4859.75 | H26: =H17-(H20+H23) -> 4671.75 | I26: =I17-(I20+I23) -> 4980.38 | J26: =J17-(J20+J23) -> 6139.28 | ... M26: =M17-(M20+M23) -> 11709.13
B27: EBT % Sales | C27: =C26/C5 -> 0.19867111 | D27: =D26/D5 -> 0.18938143 | E27: =E26/E5 -> 0.1796788 | F27: =F26/F5 -> 0.16232328 | G27: =G26/G5 -> 0.16243213 | H27: =H26/H5 -> 0.16840548 | I27: =I26/I5 -> 0.15026169 | J27: =J26/J5 -> 0.16840532 | ... M27: =M26/M5 -> 0.20286489
B29: Tax | C29: =IFERROR('Data Sheet'!B29,0) -> 1617.65 | D29: =IFERROR('Data Sheet'!C29,0) -> 1508.07 | E29: =IFERROR('Data Sheet'!D29,0) -> 1714.47 | F29: =IFERROR('Data Sheet'!E29,0) -> 2027.98 | G29: =IFERROR('Data Sheet'!F29,0) -> 1480.22 | H29: =IFERROR('Data Sheet'!G29,0) -> 1384.41 | I29: =IFERROR('Data Sheet'!H29,0) -> 1485.81 | J29: =IFERROR('Data Sheet'!I29,0) -> 1781.77 | ... M29: =IFERROR('Data Sheet'!L29,0) -> 0
B30: Effective Tax Rate % EBT | C30: =C29/C26 -> 0.36070095 | D30: =D29/D26 -> 0.36604174 | E30: =E29/E26 -> 0.3784961 | F30: =F29/F26 -> 0.41154279 | G30: =G29/G26 -> 0.30458768 | H30: =H29/H26 -> 0.29633649 | I30: =I29/I26 -> 0.29833266 | J30: =J29/J26 -> 0.29022459 | ... M30: =M29/M26 -> 0
B32: Net Profit | C32: =C26-C29 -> 2867.09 | D32: =D26-D29 -> 2611.87 | E32: =E26-E29 -> 2815.22 | F32: =F26-F29 -> 2899.77 | G32: =G26-G29 -> 3379.53 | H32: =H26-H29 -> 3287.34 | I32: =I26-I29 -> 3494.57 | J32: =J26-J29 -> 4357.51 | ... M32: =M26-M29 -> 11709.13
B33: Net Margin | C33: =C32/C5 -> 0.12701025 | D33: =D32/D5 -> 0.12005992 | E33: =E32/E5 -> 0.11167108 | F33: =F32/F5 -> 0.095520302 | G33: =G32/G5 -> 0.1129573 | H33: =H32/H5 -> 0.11850079 | I33: =I32/I5 -> 0.10543372 | J33: =J32/J5 -> 0.11952996 | ... M33: =M32/M5 -> 0.20286489
B35: No. Equity Share Holders | C35: =IFERROR('Data Sheet'!B94,0) -> 28.94 | D35: =IFERROR('Data Sheet'!C94,0) -> 28.94 | E35: =IFERROR('Data Sheet'!D94,0) -> 28.94 | F35: =IFERROR('Data Sheet'!E94,0) -> 28.94 | G35: =IFERROR('Data Sheet'!F94,0) -> 28.94 | H35: =IFERROR('Data Sheet'!G94,0) -> 28.94 | I35: =IFERROR('Data Sheet'!H94,0) -> 28.94 | J35: =IFERROR('Data Sheet'!I94,0) -> 28.3 | ... M35: =IFERROR('Data Sheet'!L94,0) -> 0
B36: Earning per share | C36: =C32/C35 -> 99.070145 | D36: =D32/D35 -> 90.251209 | E36: =E32/E35 -> 97.277816 | F36: =F32/F35 -> 100.19938 | G36: =G32/G35 -> 116.77713 | H36: =H32/H35 -> 113.59157 | I36: =I32/I35 -> 120.75225 | J36: =J32/J35 -> 153.97562 | ... M36: =M32/M35 -> #DIV/0!
B38: Dividend Per Share | C38: =IFERROR('Data Sheet'!B31/'Financials>'!C35,0) -> 54.994471 | D38: =IFERROR('Data Sheet'!C31/'Financials>'!D35,0) -> 54.994471 | E38: =IFERROR('Data Sheet'!D31/'Financials>'!E35,0) -> 59.99378 | F38: =IFERROR('Data Sheet'!E31/'Financials>'!F35,0) -> 59.99378 | G38: =IFERROR('Data Sheet'!F31/'Financials>'!G35,0) -> 119.98756 | H38: =IFERROR('Data Sheet'!G31/'Financials>'!H35,0) -> 139.98549 | I38: =IFERROR('Data Sheet'!H31/'Financials>'!I35,0) -> 139.98549 | J38: =IFERROR('Data Sheet'!I31/'Financials>'!J35,0) -> 139.98021 | ... M38: =IFERROR('Data Sheet'!L31/'Financials>'!M35,0) -> 0
B39: Dividend Payout Ratio % | C39: =C38/C35 -> 1.9002927 | D39: =D38/D35 -> 1.9002927 | E39: =E38/E35 -> 2.0730401 | F39: =F38/F35 -> 2.0730401 | G39: =G38/G35 -> 4.1460802 | H39: =H38/H35 -> 4.8370935 | I39: =I38/I35 -> 4.8370935 | J39: =J38/J35 -> 4.9462972 | ... M39: =M38/M35 -> #DIV/0!
B41: Retained Earning | C41: =IFERROR(IF(C36>C38,1-C39,0),0) -> -0.90029272 | D41: =IFERROR(IF(D36>D38,1-D39,0),0) -> -0.90029272 | E41: =IFERROR(IF(E36>E38,1-E39,0),0) -> -1.0730401 | F41: =IFERROR(IF(F36>F38,1-F39,0),0) -> -1.0730401 | G41: =IFERROR(IF(G36>G38,1-G39,0),0) -> 0 | H41: =IFERROR(IF(H36>H38,1-H39,0),0) -> 0 | I41: =IFERROR(IF(I36>I38,1-I39,0),0) -> 0 | J41: =IFERROR(IF(J36>J38,1-J39,0),0) -> -3.9462972 | ... M41: =IFERROR(IF(M36>M38,1-M39,0),0) -> 0
A43: # | B43: Balance Sheet
B44: Equity Share Capitals | C44: =IFERROR('Data Sheet'!B57,0) -> 289.37 | D44: =IFERROR('Data Sheet'!C57,0) -> 289.37 | E44: =IFERROR('Data Sheet'!D57,0) -> 289.37 | F44: =IFERROR('Data Sheet'!E57,0) -> 289.37 | G44: =IFERROR('Data Sheet'!F57,0) -> 289.37 | H44: =IFERROR('Data Sheet'!G57,0) -> 289.37 | I44: =IFERROR('Data Sheet'!H57,0) -> 289.37 | J44: =IFERROR('Data Sheet'!I57,0) -> 282.96 | ... M44: =IFERROR('Data Sheet'!L57,0) -> 0
B45: Reserves | C45: =IFERROR('Data Sheet'!B58,0) -> 13730.94 | D45: =IFERROR('Data Sheet'!C58,0) -> 17567.2 | E45: =IFERROR('Data Sheet'!D58,0) -> 20135.87 | F45: =IFERROR('Data Sheet'!E58,0) -> 22944.44 | G45: =IFERROR('Data Sheet'!F58,0) -> 21372.71 | H45: =IFERROR('Data Sheet'!G58,0) -> 26984.06 | I45: =IFERROR('Data Sheet'!H58,0) -> 29570.28 | J45: =IFERROR('Data Sheet'!I58,0) -> 29078.58 | ... M45: =IFERROR('Data Sheet'!L58,0) -> 0
B46: Borrowings | C46: =IFERROR('Data Sheet'!B59,0) -> 117.86 | D46: =IFERROR('Data Sheet'!C59,0) -> 119.9 | E46: =IFERROR('Data Sheet'!D59,0) -> 120.77 | F46: =IFERROR('Data Sheet'!E59,0) -> 124.52 | G46: =IFERROR('Data Sheet'!F59,0) -> 125.59 | H46: =IFERROR('Data Sheet'!G59,0) -> 121.46 | I46: =IFERROR('Data Sheet'!H59,0) -> 122.77 | J46: =IFERROR('Data Sheet'!I59,0) -> 124.23 | ... M46: =IFERROR('Data Sheet'!L59,0) -> 0
B47: Other Liabilities | C47: =IFERROR('Data Sheet'!B60,0) -> 3102.2 | D47: =IFERROR('Data Sheet'!C60,0) -> 3661.15 | E47: =IFERROR('Data Sheet'!D60,0) -> 4594.99 | F47: =IFERROR('Data Sheet'!E60,0) -> 5476.08 | G47: =IFERROR('Data Sheet'!F60,0) -> 4722.35 | H47: =IFERROR('Data Sheet'!G60,0) -> 6206.82 | I47: =IFERROR('Data Sheet'!H60,0) -> 5128.79 | J47: =IFERROR('Data Sheet'!I60,0) -> 5650.68 | ... M47: =IFERROR('Data Sheet'!L60,0) -> 0
B48: Total Liabilities | C48: =IFERROR('Data Sheet'!B61,0) -> 17240.37 | D48: =IFERROR('Data Sheet'!C61,0) -> 21637.62 | E48: =IFERROR('Data Sheet'!D61,0) -> 25141 | F48: =IFERROR('Data Sheet'!E61,0) -> 28834.41 | G48: =IFERROR('Data Sheet'!F61,0) -> 26510.02 | H48: =IFERROR('Data Sheet'!G61,0) -> 33601.71 | I48: =IFERROR('Data Sheet'!H61,0) -> 35111.21 | J48: =IFERROR('Data Sheet'!I61,0) -> 35136.45 | ... M48: =IFERROR('Data Sheet'!L61,0) -> 0
B50: Net Block | C50: =IFERROR('Data Sheet'!B63,0) -> 2025.67 | D50: =IFERROR('Data Sheet'!C63,0) -> 2001.79 | E50: =IFERROR('Data Sheet'!D63,0) -> 1878.33 | F50: =IFERROR('Data Sheet'!E63,0) -> 1763.94 | G50: =IFERROR('Data Sheet'!F63,0) -> 1699.02 | H50: =IFERROR('Data Sheet'!G63,0) -> 1667.55 | I50: =IFERROR('Data Sheet'!H63,0) -> 1836.05 | J50: =IFERROR('Data Sheet'!I63,0) -> 2842.24 | ... M50: =IFERROR('Data Sheet'!L63,0) -> 0
B51: Capital Work in Progress | C51: =IFERROR('Data Sheet'!B64,0) -> 52.24 | D51: =IFERROR('Data Sheet'!C64,0) -> 42.17 | E51: =IFERROR('Data Sheet'!D64,0) -> 56.47 | F51: =IFERROR('Data Sheet'!E64,0) -> 48.02 | G51: =IFERROR('Data Sheet'!F64,0) -> 60.19 | H51: =IFERROR('Data Sheet'!G64,0) -> 15.98 | I51: =IFERROR('Data Sheet'!H64,0) -> 77.21 | J51: =IFERROR('Data Sheet'!I64,0) -> 85.27 | ... M51: =IFERROR('Data Sheet'!L64,0) -> 0
B52: Investments | C52: =IFERROR('Data Sheet'!B65,0) -> 11067.23 | D52: =IFERROR('Data Sheet'!C65,0) -> 15477.04 | E52: =IFERROR('Data Sheet'!D65,0) -> 18894.57 | F52: =IFERROR('Data Sheet'!E65,0) -> 20602.85 | G52: =IFERROR('Data Sheet'!F65,0) -> 19913.58 | H52: =IFERROR('Data Sheet'!G65,0) -> 24686.65 | I52: =IFERROR('Data Sheet'!H65,0) -> 26634.12 | J52: =IFERROR('Data Sheet'!I65,0) -> 26182.91 | ... M52: =IFERROR('Data Sheet'!L65,0) -> 0
B53: Other Assets | C53: =IFERROR('Data Sheet'!B66,0) -> 4095.23 | D53: =IFERROR('Data Sheet'!C66,0) -> 4116.62 | E53: =IFERROR('Data Sheet'!D66,0) -> 4311.63 | F53: =IFERROR('Data Sheet'!E66,0) -> 6419.6 | G53: =IFERROR('Data Sheet'!F66,0) -> 4837.23 | H53: =IFERROR('Data Sheet'!G66,0) -> 7231.53 | I53: =IFERROR('Data Sheet'!H66,0) -> 6563.83 | J53: =IFERROR('Data Sheet'!I66,0) -> 6026.03 | ... M53: =IFERROR('Data Sheet'!L66,0) -> 0
B54: Total Non current Assests | C54: =IFERROR(SUM(C50:C53)-SUM(C56:C58),0) -> 14936.34 | D54: =IFERROR(SUM(D50:D53)-SUM(D56:D58),0) -> 19654.59 | E54: =IFERROR(SUM(E50:E53)-SUM(E56:E58),0) -> 22113.89 | F54: =IFERROR(SUM(F50:F53)-SUM(F56:F58),0) -> 24380.14 | G54: =IFERROR(SUM(G50:G53)-SUM(G56:G58),0) -> 23405.08 | H54: =IFERROR(SUM(H50:H53)-SUM(H56:H58),0) -> 28852.13 | I54: =IFERROR(SUM(I50:I53)-SUM(I56:I58),0) -> 31406.26 | J54: =IFERROR(SUM(J50:J53)-SUM(J56:J58),0) -> 31129.99 | ... M54: =IFERROR(SUM(M50:M53)-SUM(M56:M58),0) -> 0
B56: Receivables | C56: =IFERROR('Data Sheet'!B68,0) -> 717.93 | D56: =IFERROR('Data Sheet'!C68,0) -> 953.29 | E56: =IFERROR('Data Sheet'!D68,0) -> 1491.87 | F56: =IFERROR('Data Sheet'!E68,0) -> 2559.69 | G56: =IFERROR('Data Sheet'!F68,0) -> 1725.1 | H56: =IFERROR('Data Sheet'!G68,0) -> 2716.85 | I56: =IFERROR('Data Sheet'!H68,0) -> 1516.38 | J56: =IFERROR('Data Sheet'!I68,0) -> 1752.43 | ... M56: =IFERROR('Data Sheet'!L68,0) -> 0
...

Sheet Common Size Statement
B2: ="Common Size Income Statement"&" - "&" "&'Data Sheet'!$B$1 -> Common Size Income Statement - BAJAJ AUTO LTD
B4: Particulars | C4: ='Data Sheet'!B16 -> 42460 | D4: ='Data Sheet'!C16 -> 42825 | E4: ='Data Sheet'!D16 -> 43190 | F4: ='Data Sheet'!E16 -> 43555 | G4: ='Data Sheet'!F16 -> 43921 | H4: ='Data Sheet'!G16 -> 44286 | I4: ='Data Sheet'!H16 -> 44651 | J4: ='Data Sheet'!I16 -> 45016 | ... L4: ='Data Sheet'!K16 -> 45747
B6: ='Data Sheet'!A17 -> Sales | C6: ='Data Sheet'!B17/'Data Sheet'!B$17 -> 1 | D6: ='Data Sheet'!C17/'Data Sheet'!C$17 -> 1 | E6: ='Data Sheet'!D17/'Data Sheet'!D$17 -> 1 | F6: ='Data Sheet'!E17/'Data Sheet'!E$17 -> 1 | G6: ='Data Sheet'!F17/'Data Sheet'!F$17 -> 1 | H6: ='Data Sheet'!G17/'Data Sheet'!G$17 -> 1 | I6: ='Data Sheet'!H17/'Data Sheet'!H$17 -> 1 | J6: ='Data Sheet'!I17/'Data Sheet'!I$17 -> 1 | ... L6: ='Data Sheet'!K17/'Data Sheet'!K$17 -> 1
B7: ='Data Sheet'!A18 -> Raw Material Cost | C7: ='Data Sheet'!B18/'Data Sheet'!B$17 -> 0.66419845 | D7: ='Data Sheet'!C18/'Data Sheet'!C$17 -> 0.67423667 | E7: ='Data Sheet'!D18/'Data Sheet'!D$17 -> 0.69022048 | F7: ='Data Sheet'!E18/'Data Sheet'!E$17 -> 0.71988821 | G7: ='Data Sheet'!F18/'Data Sheet'!F$17 -> 0.70428612 | H7: ='Data Sheet'!G18/'Data Sheet'!G$17 -> 0.71479301 | I7: ='Data Sheet'!H18/'Data Sheet'!H$17 -> 0.72837747 | J7: ='Data Sheet'!I18/'Data Sheet'!I$17 -> 0.71927875 | ... L7: ='Data Sheet'!K18/'Data Sheet'!K$17 -> 0.69087344
B8: ='Data Sheet'!A19 -> Change in Inventory | C8: ='Data Sheet'!B19/'Data Sheet'!B$17 -> -0.0028107943 | D8: ='Data Sheet'!C19/'Data Sheet'!C$17 -> 0.0020078401 | E8: ='Data Sheet'!D19/'Data Sheet'!D$17 -> -0.00038397568 | F8: ='Data Sheet'!E19/'Data Sheet'!E$17 -> 0.0018585114 | G8: ='Data Sheet'!F19/'Data Sheet'!F$17 -> 0.0021060442 | H8: ='Data Sheet'!G19/'Data Sheet'!G$17 -> 0.0079117323 | I8: ='Data Sheet'!H19/'Data Sheet'!H$17 -> -0.0056708899 | J8: ='Data Sheet'!I19/'Data Sheet'!I$17 -> 0.0027521315 | ... L8: ='Data Sheet'!K19/'Data Sheet'!K$17 -> -0.00055711836
B9: ='Data Sheet'!A20 -> Power and Fuel | C9: ='Data Sheet'!B20/'Data Sheet'!B$17 -> 0.0053451607 | D9: ='Data Sheet'!C20/'Data Sheet'!C$17 -> 0.0044339803 | E9: ='Data Sheet'!D20/'Data Sheet'!D$17 -> 0.0039770043 | F9: ='Data Sheet'!E20/'Data Sheet'!E$17 -> 0.0037885039 | G9: ='Data Sheet'!F20/'Data Sheet'!F$17 -> 0.0038962319 | H9: ='Data Sheet'!G20/'Data Sheet'!G$17 -> 0.0032925899 | I9: ='Data Sheet'!H20/'Data Sheet'!H$17 -> 0.0032587402 | J9: ='Data Sheet'!I20/'Data Sheet'!I$17 -> 0.0033630153 | ... L9: ='Data Sheet'!K20/'Data Sheet'!K$17 -> 0.0034697826
B10: ='Data Sheet'!A21 -> Other Mfr. Exp | C10: ='Data Sheet'!B21/'Data Sheet'!B$17 -> 0.028537204 | D10: ='Data Sheet'!C21/'Data Sheet'!C$17 -> 0.025168791 | E10: ='Data Sheet'!D21/'Data Sheet'!D$17 -> 0.021823147 | F10: ='Data Sheet'!E21/'Data Sheet'!E$17 -> 0.020884041 | G10: ='Data Sheet'!F21/'Data Sheet'!F$17 -> 0.023357672 | H10: ='Data Sheet'!G21/'Data Sheet'!G$17 -> 0.021524396 | I10: ='Data Sheet'!H21/'Data Sheet'!H$17 -> 0.025231176 | J10: ='Data Sheet'!I21/'Data Sheet'!I$17 -> 0.020396166 | ... L10: ='Data Sheet'!K21/'Data Sheet'!K$17 -> 0.015992101
B11: ='Data Sheet'!A22 -> Employee Cost | C11: ='Data Sheet'!B22/'Data Sheet'!B$17 -> 0.040755853 | D11: ='Data Sheet'!C22/'Data Sheet'!C$17 -> 0.045959222 | E11: ='Data Sheet'!D22/'Data Sheet'!D$17 -> 0.04254633 | F11: ='Data Sheet'!E22/'Data Sheet'!E$17 -> 0.041515757 | G11: ='Data Sheet'!F22/'Data Sheet'!F$17 -> 0.046626435 | H11: ='Data Sheet'!G22/'Data Sheet'!G$17 -> 0.046720243 | I11: ='Data Sheet'!H22/'Data Sheet'!H$17 -> 0.041213213 | J11: ='Data Sheet'!I22/'Data Sheet'!I$17 -> 0.040819764 | ... L11: ='Data Sheet'!K22/'Data Sheet'!K$17 -> 0.037854633
B12: ='Data Sheet'!A23 -> Selling and admin | C12: ='Data Sheet'!B23/'Data Sheet'!B$17 -> 0.035247228 | D12: ='Data Sheet'!C23/'Data Sheet'!C$17 -> 0.032164514 | E12: ='Data Sheet'!D23/'Data Sheet'!D$17 -> 0.033828733 | F12: ='Data Sheet'!E23/'Data Sheet'!E$17 -> 0.030994514 | G12: ='Data Sheet'!F23/'Data Sheet'!F$17 -> 0.034125203 | H12: ='Data Sheet'!G23/'Data Sheet'!G$17 -> 0.023606147 | I12: ='Data Sheet'!H23/'Data Sheet'!H$17 -> 0.019457102 | J12: ='Data Sheet'!I23/'Data Sheet'!I$17 -> 0.023387769 | ... L12: ='Data Sheet'!K23/'Data Sheet'!K$17 -> 0.024304166
B13: ='Data Sheet'!A24 -> Other Expenses | C13: ='Data Sheet'!B24/'Data Sheet'!B$17 -> 0.010780692 | D13: ='Data Sheet'!C24/'Data Sheet'!C$17 -> 0.016473666 | E13: ='Data Sheet'!D24/'Data Sheet'!D$17 -> 0.015002422 | F13: ='Data Sheet'!E24/'Data Sheet'!E$17 -> 0.013564629 | G13: ='Data Sheet'!F24/'Data Sheet'!F$17 -> 0.019039963 | H13: ='Data Sheet'!G24/'Data Sheet'!G$17 -> 0.019980116 | I13: ='Data Sheet'!H24/'Data Sheet'!H$17 -> 0.01812959 | J13: ='Data Sheet'!I24/'Data Sheet'!I$17 -> 0.018176467 | ... L13: ='Data Sheet'!K24/'Data Sheet'!K$17 -> 0.039583642
B14: ='Data Sheet'!A25 -> Other Income | C14: ='Data Sheet'!B25/'Data Sheet'!B$17 -> 0.05290008 | D14: ='Data Sheet'!C25/'Data Sheet'!C$17 -> 0.067461682 | E14: ='Data Sheet'!D25/'Data Sheet'!D$17 -> 0.055681234 | F14: ='Data Sheet'!E25/'Data Sheet'!E$17 -> 0.066798034 | G14: ='Data Sheet'!F25/'Data Sheet'!F$17 -> 0.06124541 | H14: ='Data Sheet'!G25/'Data Sheet'!G$17 -> 0.056583233 | I14: ='Data Sheet'!H25/'Data Sheet'!H$17 -> 0.080595063 | J14: ='Data Sheet'!I25/'Data Sheet'!I$17 -> 0.046706412 | ... L14: ='Data Sheet'!K25/'Data Sheet'!K$17 -> 0.028867006
B15: ='Data Sheet'!A26 -> Depreciation | C15: ='Data Sheet'!B26/'Data Sheet'!B$17 -> 0.013606991 | D15: ='Data Sheet'!C26/'Data Sheet'!C$17 -> 0.014125211 | E15: ='Data Sheet'!D26/'Data Sheet'!D$17 -> 0.012487143 | F15: ='Data Sheet'!E26/'Data Sheet'!E$17 -> 0.0087520007 | G15: ='Data Sheet'!F26/'Data Sheet'!F$17 -> 0.0082366684 | H15: ='Data Sheet'!G26/'Data Sheet'!G$17 -> 0.009349672 | I15: ='Data Sheet'!H26/'Data Sheet'!H$17 -> 0.0081388553 | J15: ='Data Sheet'!I26/'Data Sheet'!I$17 -> 0.0078410923 | ... L15: ='Data Sheet'!K26/'Data Sheet'!K$17 -> 0.0081230249
B16: ='Data Sheet'!A27 -> Interest | C16: ='Data Sheet'!B27/'Data Sheet'!B$17 -> 4.6514327e-05 | D16: ='Data Sheet'!C27/'Data Sheet'!C$17 -> 6.4353851e-05 | E16: ='Data Sheet'!D27/'Data Sheet'!D$17 -> 5.1963651e-05 | F16: ='Data Sheet'!E27/'Data Sheet'!E$17 -> 0.0001475741 | G16: ='Data Sheet'!F27/'Data Sheet'!F$17 -> 0.00010561974 | H16: ='Data Sheet'!G27/'Data Sheet'!G$17 -> 0.00024007717 | I16: ='Data Sheet'!H27/'Data Sheet'!H$17 -> 0.0002612785 | J16: ='Data Sheet'!I27/'Data Sheet'!I$17 -> 0.0010837907 | ... L16: ='Data Sheet'!K27/'Data Sheet'!K$17 -> 0.0076263052
B17: ='Data Sheet'!A28 -> Profit before tax | C17: ='Data Sheet'!B28/'Data Sheet'!B$17 -> 0.25157119 | D17: ='Data Sheet'!C28/'Data Sheet'!C$17 -> 0.25684311 | E17: ='Data Sheet'!D28/'Data Sheet'!D$17 -> 0.23536003 | F17: ='Data Sheet'!E28/'Data Sheet'!E$17 -> 0.22912131 | G17: ='Data Sheet'!F28/'Data Sheet'!F$17 -> 0.22367754 | H17: ='Data Sheet'!G28/'Data Sheet'!G$17 -> 0.22498872 | I17: ='Data Sheet'!H28/'Data Sheet'!H$17 -> 0.23085675 | J17: ='Data Sheet'!I28/'Data Sheet'!I$17 -> 0.21511173 | ... L17: ='Data Sheet'!K28/'Data Sheet'!K$17 -> 0.2004828
... B20: ='Data Sheet'!A31 -> Dividend Amount | C20: ='Data Sheet'!B31/'Data Sheet'!B$17 -> 0.070504202 | D20: ='Data Sheet'!C31/'Data Sheet'!C$17 -> 0.073158377 | E20: ='Data Sheet'!D31/'Data Sheet'!D$17 -> 0.068870481 | F20: ='Data Sheet'!E31/'Data Sheet'!E$17 -> 0.057192212 | G20: ='Data Sheet'!F31/'Data Sheet'!F$17 -> 0.11606272 | H20: ='Data Sheet'!G31/'Data Sheet'!G$17 -> 0.14603541 | I20: ='Data Sheet'!H31/'Data Sheet'!H$17 -> 0.12222705 | J20: ='Data Sheet'!I31/'Data Sheet'!I$17 -> 0.10866544 | ... L20: ='Data Sheet'!K31/'Data Sheet'!K$17 -> 0.1150017
B21: ='Data Sheet'!A33 -> EBITDA | C21: ='Data Sheet'!B33/'Data Sheet'!B$17 -> 0.26522469 | D21: ='Data Sheet'!C33/'Data Sheet'!C$17 -> 0.27103314 | E21: ='Data Sheet'!D33/'Data Sheet'!D$17 -> 0.24789954 | F21: ='Data Sheet'!E33/'Data Sheet'!E$17 -> 0.23802122 | G21: ='Data Sheet'!F33/'Data Sheet'!F$17 -> 0.23201983 | H21: ='Data Sheet'!G33/'Data Sheet'!G$17 -> 0.23457847 | I21: ='Data Sheet'!H33/'Data Sheet'!H$17 -> 0.23925688 | J21: ='Data Sheet'!I33/'Data Sheet'!I$17 -> 0.22403662 | ... L21: ='Data Sheet'!K33/'Data Sheet'!K$17 -> 0.21623213
B23: ="Common Size Balance Sheet"&" - "&" "&'Data Sheet'!$B$1 -> Common Size Balance Sheet - BAJAJ AUTO LTD
B25: Particulars | C25: ='Data Sheet'!B56 -> 42460 | D25: ='Data Sheet'!C56 -> 42825 | E25: ='Data Sheet'!D56 -> 43190 | F25: ='Data Sheet'!E56 -> 43555 | G25: ='Data Sheet'!F56 -> 43921 | H25: ='Data Sheet'!G56 -> 44286 | I25: ='Data Sheet'!H56 -> 44651 | J25: ='Data Sheet'!I56 -> 45016 | ... L25: ='Data Sheet'!K56 -> 45747
B27: Total Liabilities | C27: ='Data Sheet'!B61/'Data Sheet'!B$61 -> 1 | D27: ='Data Sheet'!C61/'Data Sheet'!C$61 -> 1 | E27: ='Data Sheet'!D61/'Data Sheet'!D$61 -> 1 | F27: ='Data Sheet'!E61/'Data Sheet'!E$61 -> 1 | G27: ='Data Sheet'!F61/'Data Sheet'!F$61 -> 1 | H27: ='Data Sheet'!G61/'Data Sheet'!G$61 -> 1 | I27: ='Data Sheet'!H61/'Data Sheet'!H$61 -> 1 | J27: ='Data Sheet'!I61/'Data Sheet'!I$61 -> 1 | ... L27: ='Data Sheet'!K61/'Data Sheet'!K$61 -> 1
B28: ='Data Sheet'!A57 -> Equity Share Capital | C28: ='Data Sheet'!B57/'Data Sheet'!B$61 -> 0.016784443 | D28: ='Data Sheet'!C57/'Data Sheet'!C$61 -> 0.013373467 | E28: ='Data Sheet'!D57/'Data Sheet'!D$61 -> 0.011509884 | F28: ='Data Sheet'!E57/'Data Sheet'!E$61 -> 0.010035579 | G28: ='Data Sheet'!F57/'Data Sheet'!F$61 -> 0.010915495 | H28: ='Data Sheet'!G57/'Data Sheet'!G$61 -> 0.0086117641 | I28: ='Data Sheet'!H57/'Data Sheet'!H$61 -> 0.0082415274 | J28: ='Data Sheet'!I57/'Data Sheet'!I$61 -> 0.0080531755 | ... L28: ='Data Sheet'!K57/'Data Sheet'!K$61 -> 0.005160976
B29: ='Data Sheet'!A58 -> Reserves | C29: ='Data Sheet'!B58/'Data Sheet'!B$61 -> 0.79644114 | D29: ='Data Sheet'!C58/'Data Sheet'!C$61 -> 0.81188227 | E29: ='Data Sheet'!D58/'Data Sheet'!D$61 -> 0.80091762 | F29: ='Data Sheet'!E58/'Data Sheet'!E$61 -> 0.79573121 | G29: ='Data Sheet'!F58/'Data Sheet'!F$61 -> 0.80621252 | H29: ='Data Sheet'!G58/'Data Sheet'!G$61 -> 0.80305615 | I29: ='Data Sheet'!H58/'Data Sheet'!H$61 -> 0.84218915 | J29: ='Data Sheet'!I58/'Data Sheet'!I$61 -> 0.82759015 | ... L29: ='Data Sheet'!K58/'Data Sheet'!K$61 -> 0.6451586
B30: ='Data Sheet'!A59 -> Borrowings | C30: ='Data Sheet'!B59/'Data Sheet'!B$61 -> 0.0068362802 | D30: ='Data Sheet'!C59/'Data Sheet'!C$61 -> 0.0055412749 | E30: ='Data Sheet'!D59/'Data Sheet'!D$61 -> 0.0048037071 | F30: ='Data Sheet'!E59/'Data Sheet'!E$61 -> 0.0043184515 | G30: ='Data Sheet'!F59/'Data Sheet'!F$61 -> 0.004737454 | H30: ='Data Sheet'!G59/'Data Sheet'!G$61 -> 0.003614697 | I30: ='Data Sheet'!H59/'Data Sheet'!H$61 -> 0.0034966041 | J30: ='Data Sheet'!I59/'Data Sheet'!I$61 -> 0.0035356446 | ... L30: ='Data Sheet'!K59/'Data Sheet'!K$61 -> 0.1730581
B31: ='Data Sheet'!A60 -> Other Liabilities | C31: ='Data Sheet'!B60/'Data Sheet'!B$61 -> 0.17993813 | D31: ='Data Sheet'!C60/'Data Sheet'!C$61 -> 0.16920299 | E31: ='Data Sheet'!D60/'Data Sheet'!D$61 -> 0.18276878 | F31: ='Data Sheet'!E60/'Data Sheet'!E$61 -> 0.18991476 | G31: ='Data Sheet'!F60/'Data Sheet'!F$61 -> 0.17813453 | H31: ='Data Sheet'!G60/'Data Sheet'!G$61 -> 0.18471738 | I31: ='Data Sheet'!H60/'Data Sheet'!H$61 -> 0.14607272 | J31: ='Data Sheet'!I60/'Data Sheet'!I$61 -> 0.16082103 | ... L31: ='Data Sheet'!K60/'Data Sheet'!K$61 -> 0.17662233
B33: Total Assets | C33: ='Data Sheet'!B67/'Data Sheet'!B$67 -> 1 | D33: ='Data Sheet'!C67/'Data Sheet'!C$67 -> 1 | E33: ='Data Sheet'!D67/'Data Sheet'!D$67 -> 1 | F33: ='Data Sheet'!E67/'Data Sheet'!E$67 -> 1 | G33: ='Data Sheet'!F67/'Data Sheet'!F$67 -> 1 | H33: ='Data Sheet'!G67/'Data Sheet'!G$67 -> 1 | I33: ='Data Sheet'!H67/'Data Sheet'!H$67 -> 1 | J33: ='Data Sheet'!I67/'Data Sheet'!I$67 -> 1 | ... L33: ='Data Sheet'!K67/'Data Sheet'!K$67 -> 1
B34: ='Data Sheet'!A63 -> Net Block | C34: ='Data Sheet'!B63/'Data Sheet'!B$67 -> 0.11749574 | D34: ='Data Sheet'!C63/'Data Sheet'!C$67 -> 0.092514334 | E34: ='Data Sheet'!D63/'Data Sheet'!D$67 -> 0.074711825 | F34: ='Data Sheet'!E63/'Data Sheet'!E$67 -> 0.061174825 | G34: ='Data Sheet'!F63/'Data Sheet'!F$67 -> 0.064089729 | H34: ='Data Sheet'!G63/'Data Sheet'!G$67 -> 0.049626939 | I34: ='Data Sheet'!H63/'Data Sheet'!H$67 -> 0.052292416 | J34: ='Data Sheet'!I63/'Data Sheet'!I$67 -> 0.080891496 | ... L34: ='Data Sheet'!K63/'Data Sheet'!K$67 -> 0.067946691
B35: ='Data Sheet'!A64 -> Capital Work in Progress | C35: ='Data Sheet'!B64/'Data Sheet'!B$67 -> 0.0030300974 | D35: ='Data Sheet'!C64/'Data Sheet'!C$67 -> 0.0019489204 | E35: ='Data Sheet'!D64/'Data Sheet'!D$67 -> 0.0022461318 | F35: ='Data Sheet'!E64/'Data Sheet'!E$67 -> 0.0016653713 | G35: ='Data Sheet'!F64/'Data Sheet'!F$67 -> 0.0022704623 | H35: ='Data Sheet'!G64/'Data Sheet'!G$67 -> 0.00047557103 | I35: ='Data Sheet'!H64/'Data Sheet'!H$67 -> 0.0021990128 | J35: ='Data Sheet'!I64/'Data Sheet'!I$67 -> 0.0024268246 | ... L35: ='Data Sheet'!K64/'Data Sheet'!K$67 -> 0.0011236387
B36: ='Data Sheet'!A65 -> Investments | C36: ='Data Sheet'!B65/'Data Sheet'!B$67 -> 0.64193692 | D36: ='Data Sheet'!C65/'Data Sheet'!C$67 -> 0.71528384 | E36: ='Data Sheet'!D65/'Data Sheet'!D$67 -> 0.75154409 | F36: ='Data Sheet'!E65/'Data Sheet'!E$67 -> 0.71452303 | G36: ='Data Sheet'!F65/'Data Sheet'!F$67 -> 0.75117182 | H36: ='Data Sheet'!G65/'Data Sheet'!G$67 -> 0.73468434 | I36: ='Data Sheet'!H65/'Data Sheet'!H$67 -> 0.75856457 | J36: ='Data Sheet'!I65/'Data Sheet'!I$67 -> 0.74517801 | ... L36: ='Data Sheet'!K65/'Data Sheet'!K$67 -> 0.53435433
B37: ='Data Sheet'!A66 -> Other Assets | C37: ='Data Sheet'!B66/'Data Sheet'!B$67 -> 0.23753725 | D37: ='Data Sheet'!C66/'Data Sheet'!C$67 -> 0.1902529 | E37: ='Data Sheet'!D66/'Data Sheet'!D$67 -> 0.17149795 | F37: ='Data Sheet'!E66/'Data Sheet'!E$67 -> 0.22263677 | G37: ='Data Sheet'!F66/'Data Sheet'!F$67 -> 0.18246799 | H37: ='Data Sheet'!G66/'Data Sheet'!G$67 -> 0.21521315 | I37: ='Data Sheet'!H66/'Data Sheet'!H$67 -> 0.186944 | J37: ='Data Sheet'!I66/'Data Sheet'!I$67 -> 0.17150367 | ... L37: ='Data Sheet'!K66/'Data Sheet'!K$67 -> 0.39657534

Sheet Cashflow Data
C2: 42430 | D2: 42795 | E2: 43160 | F2: 43525 | G2: 43891 | H2: 44256 | I2: 44621 | J2: 44986 | K2: 45352 | L2: 45717
B3: Cash from Operating Activity - | C3: 3690 | D3: 3267 | E3: 4328 | F3: 2487 | G3: 3850 | H3: 3120 | I3: 4197 | J3: 5277 | K3: 6558 | L3: -1406
B4: Profit from operations | C4: 4930 | D4: 4613 | E4: 4922 | F4: 5249 | G4: 5163 | H4: 4961 | I4: 5300 | J4: 6609 | K4: 8784 | L4: 10404
B5: Receivables | C5: -5 | D5: -241 | E5: -539 | F5: -1070 | G5: 829 | H5: -1002 | I5: 1203 | J5: -243 | K5: -293 | L5: -52
B6: Inventory | C6: 95 | D6: -9 | E6: -14 | F6: -219 | G6: -102 | H6: -430 | I6: 263 | J6: -333 | K6: -125 | L6: -389
B7: Loans Advances | C7: 0 | D7: 0 | E7: 0 | F7: 0 | G7: 0 | H7: 0 | I7: 0 | J7: 0 | K7: 0 | L7: -9848
B8: Other WC items | C8: 489 | D8: 407 | E8: 1644 | F8: 491 | G8: -361 | H8: 931 | I8: -867 | J8: 1164 | K8: 579 | L8: 1229
B9: Working capital changes | C9: 579 | D9: 157 | E9: 1091 | F9: -798 | G9: 366 | H9: -501 | I9: 599 | J9: 587 | K9: 161 | L9: -9060
B10: Direct taxes | C10: -1819 | D10: -1503 | E10: -1685 | F10: -1964 | G10: -1678 | H10: -1340 | I10: -1702 | J10: -1919 | K10: -2387 | L10: -2750
B11: Cash from Investing Activity - | C11: -68 | D11: -3610 | E11: -1954 | F11: -273 | G11: 1766 | H11: -2869 | I11: 276 | J11: 1211 | K11: -72 | L11: -1053
B12: Fixed assets purchased | C12: -271 | D12: -206 | E12: -196 | F12: -184 | G12: -297 | H12: -260 | I12: -551 | J12: -1110 | K12: -723 | L12: -874
B13: Fixed assets sold | C13: 0 | D13: 9 | E13: 13 | F13: 76 | G13: 17 | H13: 6 | I13: 33 | J13: 137 | K13: 12 | L13: 6
B14: Investments purchased | C14: -6263 | D14: -5783 | E14: -7484 | F14: -9601 | G14: -3518 | H14: -6240 | I14: -11293 | J14: -9384 | K14: -17365 | L14: -11897
... B27: Net Cash Flow | C27: 238 | D27: -532 | E27: 488 | F27: 140 | G27: -630 | H27: 231 | I27: 417 | J27: -692 | K27: 319 | L27: 1771

Sheet Data Sheet
A1: COMPANY NAME | B1: BAJAJ AUTO LTD | E1: =IF(B2<>B3, "A NEW VERSION OF THE WORKSHEET IS AVAILABLE", "")
A2: LATEST VERSION | B2: 2.1 | E2: PLEASE DO NOT MAKE ANY CHANGES TO THIS SHEET
A3: CURRENT VERSION | B3: 2.1
A5: META
A6: Number of shares | B6: =IF(B9>0, B9/B8, 0) -> 27.94633
A7: Face Value | B7: 10
A8: Current Price | B8: 9049.7
A9: Market Capitalization | B9: 252905.9
A15: PROFIT & LOSS
A16: Report Date | B16: 42460 | C16: 42825 | D16: 43190 | E16: 43555 | F16: 43921 | G16: 44286 | H16: 44651 | I16: 45016 | J16: 45382 | K16: 45747
A17: Sales | B17: 22573.69 | C17: 21754.72 | D17: 25209.93 | E17: 30357.63 | F17: 29918.65 | G17: 27741.08 | H17: 33144.71 | I17: 36455.38 | J17: 44870.43 | K17: 50994.55
A18: Raw Material Cost | B18: 14993.41 | C18: 14667.83 | D18: 17400.41 | E18: 21854.1 | F18: 21071.29 | G18: 19829.13 | H18: 24141.86 | I18: 26221.58 | J18: 31969.57 | K18: 35230.78
A19: Change in Inventory | B19: -63.45 | C19: 43.68 | D19: -9.68 | E19: 56.42 | F19: 63.01 | G19: 219.48 | H19: -187.96 | I19: 100.33 | J19: 76.34 | K19: -28.41
A20: Power and Fuel | B20: 120.66 | C20: 96.46 | D20: 100.26 | E20: 115.01 | F20: 116.57 | G20: 91.34 | H20: 108.01 | I20: 122.6 | J20: 147.94 | K20: 176.94
A21: Other Mfr. Exp | B21: 644.19 | C21: 547.54 | D21: 550.16 | E21: 633.99 | F21: 698.83 | G21: 597.11 | H21: 836.28 | I21: 743.55 | J21: 734.43 | K21: 815.51
A22: Employee Cost | B22: 920.01 | C22: 999.83 | D22: 1072.59 | E22: 1260.32 | F22: 1395 | G22: 1296.07 | H22: 1366 | I22: 1488.1 | J22: 1631.06 | K22: 1930.38
A23: Selling and admin | B23: 795.66 | C23: 699.73 | D23: 852.82 | E23: 940.92 | F23: 1020.98 | G23: 654.86 | H23: 644.9 | I23: 852.61 | J23: 999.37 | K23: 1239.38
A24: Other Expenses | B24: 243.36 | C24: 358.38 | D24: 378.21 | E24: 411.79 | F24: 569.65 | G24: 554.27 | H24: 600.9 | I24: 662.63 | J24: 699.72 | K24: 2018.55
A25: Other Income | B25: 1194.15 | C25: 1467.61 | D25: 1403.72 | E25: 2027.83 | F25: 1832.38 | G25: 1569.68 | H25: 2671.3 | I25: 1702.7 | J25: 1700.49 | K25: 1472.06
A26: Depreciation | B26: 307.16 | C26: 307.29 | D26: 314.8 | E26: 265.69 | F26: 246.43 | G26: 259.37 | H26: 269.76 | I26: 285.85 | J26: 364.77 | K26: 414.23
A27: Interest | B27: 1.05 | C27: 1.4 | D27: 1.31 | E27: 4.48 | F27: 3.16 | G27: 6.66 | H27: 8.66 | I27: 39.51 | J27: 60.36 | K27: 388.9
... A31: Dividend Amount | B31: 1591.54 | C31: 1591.54 | D31: 1736.22 | E31: 1736.22 | F31: 3472.44 | G31: 4051.18 | H31: 4051.18 | I31: 3961.44 | J31: 2233.44 | K31: 5864.46
A33: EBITDA | B33: =SUM(B30,B29,B27,B26,) -> 5987.1 | C33: =SUM(C30,C29,C27,C26,) -> 5896.25 | D33: =SUM(D30,D29,D27,D26,) -> 6249.53 | E33: =SUM(E30,E29,E27,E26,) -> 7225.76 | F33: =SUM(F30,F29,F27,F26,) -> 6941.72 | G33: =SUM(G30,G29,G27,G26,) -> 6507.46 | H33: =SUM(H30,H29,H27,H26,) -> 7930.1 | I33: =SUM(I30,I29,I27,I26,) -> 8167.34 | ... K33: =SUM(K30,K29,K27,K26,) -> 11026.66
A40: Quarters
A41: Report Date | B41: 45199 | C41: 45291 | D41: 45382 | E41: 45473 | F41: 45565 | G41: 45657 | H41: 45747 | I41: 45838 | J41: 45930 | K41: 46022
A42: Sales | B42: 10838.24 | C42: 12165.33 | D42: 11554.95 | E42: 11932.07 | F42: 13247.28 | G42: 13168.88 | H42: 12646.32 | I42: 13133.35 | J42: 15734.74 | K42: 16204.45
A43: Expenses | B43: 8708.11 | C43: 9750.43 | D43: 9270.69 | E43: 9561.63 | F43: 11174.05 | G43: 10418.05 | H43: 10288.57 | I43: 10340.41 | J43: 12906.05 | K43: 12474.7
A44: Other Income | B44: 552.25 | C44: 356.33 | D44: 443.93 | E44: 335.32 | F44: 399.33 | G44: 347.53 | H44: 392.23 | I44: 508.98 | J44: 575.8 | K44: 359.31
A45: Depreciation | B45: 91.82 | C45: 92.91 | D45: 92.81 | E45: 95.01 | F45: 98.27 | G45: 101.72 | H45: 119.23 | I45: 117.51 | J45: 118.99 | K45: 119.26
A46: Interest | B46: 6.54 | C46: 12.1 | D46: 29.63 | E46: 46.97 | F46: 75.2 | G46: 120.21 | H46: 146.52 | I46: 223.76 | J46: 286.84 | K46: 313.63
A47: Profit before tax | B47: 2584.02 | C47: 2666.22 | D47: 2605.75 | E47: 2563.78 | F47: 2299.09 | G47: 2876.43 | H47: 2484.23 | I47: 2960.65 | J47: 2998.66 | K47: 3656.17
A48: Tax | B48: 563.97 | C48: 633.6 | D48: 594.32 | E48: 621.99 | F48: 913.65 | G48: 680.78 | H48: 682.38 | I48: 750.21 | J48: 876.63 | K48: 906.35
A49: Net profit | B49: 2020.05 | C49: 2032.62 | D49: 2011.43 | E49: 1941.79 | F49: 1385.44 | G49: 2195.65 | H49: 1801.85 | I49: 2210.44 | J49: 2122.03 | K49: 2749.82
A50: Operating Profit | B50: 2130.13 | C50: 2414.9 | D50: 2284.26 | E50: 2370.44 | F50: 2073.23 | G50: 2750.83 | H50: 2357.75 | I50: 2792.94 | J50: 2828.69 | K50: 3729.75
A55: BALANCE SHEET
A56: Report Date | B56: 42460 | C56: 42825 | D56: 43190 | E56: 43555 | F56: 43921 | G56: 44286 | H56: 44651 | I56: 45016 | J56: 45382 | K56: 45747
A57: Equity Share Capital | B57: 289.37 | C57: 289.37 | D57: 289.37 | E57: 289.37 | F57: 289.37 | G57: 289.37 | H57: 289.37 | I57: 282.96 | J57: 279.18 | K57: 279.26
A58: Reserves | B58: 13730.94 | C58: 17567.2 | D58: 20135.87 | E58: 22944.44 | F58: 21372.71 | G58: 26984.06 | H58: 29570.28 | I58: 29078.58 | J58: 28683.23 | K58: 34909.48
A59: Borrowings | B59: 117.86 | C59: 119.9 | D59: 120.77 | E59: 124.52 | F59: 125.59 | G59: 121.46 | H59: 122.77 | I59: 124.23 | J59: 1911.74 | K59: 9364.16
A60: Other Liabilities | B60: 3102.2 | C60: 3661.15 | D60: 4594.99 | E60: 5476.08 | F60: 4722.35 | G60: 6206.82 | H60: 5128.79 | I60: 5650.68 | J60: 8469.54 | K60: 9557.02
...
