Workbook
Name UPDATE: 'Data Sheet'!$E$1

Sheet Profit & Loss
A1: ='Data Sheet'!B1 -> ETERNAL LTD | H1: =UPDATE | M1: SCREENER.IN
A3: Narration | B3: ='Data Sheet'!B16 -> 0 | C3: ='Data Sheet'!C16 -> 0 | D3: ='Data Sheet'!D16 -> 43190 | E3: ='Data Sheet'!E16 -> 43555 | F3: ='Data Sheet'!F16 -> 43921 | G3: ='Data Sheet'!G16 -> 44286 | H3: ='Data Sheet'!H16 -> 44651 | I3: ='Data Sheet'!I16 -> 45016 | ... K3: ='Data Sheet'!K16 -> 45747 | L3: Trailing | M3: Best Case | N3: Worst Case
A4: Sales | B4: ='Data Sheet'!B17 -> 0 | C4: ='Data Sheet'!C17 -> 0 | D4: ='Data Sheet'!D17 -> 466.02 | E4: ='Data Sheet'!E17 -> 1312.59 | F4: ='Data Sheet'!F17 -> 2604.74 | G4: ='Data Sheet'!G17 -> 1993.8 | H4: ='Data Sheet'!H17 -> 4192.4 | I4: ='Data Sheet'!I17 -> 7079 | ... K4: ='Data Sheet'!K17 -> 20243 | L4: =SUM(Quarters!H4:K4) -> 42905 | M4: =$K4+M23*K4 -> 42905 | N4: =$K4+N23*L4 -> 41994.175 | P4: =(Annual[[#This Row],[Column11]]-Annual[[#This Row],[Column10]])/Annual[[#This Row],[Column10]] -> 0.67104177
A5: Expenses | B5: =SUM('Data Sheet'!B18,'Data Sheet'!B20:B24, -1*'Data Sheet'!B19) -> 0 | C5: =SUM('Data Sheet'!C18,'Data Sheet'!C20:C24, -1*'Data Sheet'!C19) -> 0 | D5: =SUM('Data Sheet'!D18,'Data Sheet'!D20:D24, -1*'Data Sheet'!D19) -> 558.47 | E5: =SUM('Data Sheet'!E18,'Data Sheet'!E20:E24, -1*'Data Sheet'!E19) -> 3556.07 | F5: =SUM('Data Sheet'!F18,'Data Sheet'!F20:F24, -1*'Data Sheet'!F19) -> 4909.44 | G5: =SUM('Data Sheet'!G18,'Data Sheet'!G20:G24, -1*'Data Sheet'!G19) -> 2460.9 | H5: =SUM('Data Sheet'!H18,'Data Sheet'!H20:H24, -1*'Data Sheet'!H19) -> 6043.2 | I5: =SUM('Data Sheet'!I18,'Data Sheet'!I20:I24, -1*'Data Sheet'!I19) -> 8290 | ... K5: =SUM('Data Sheet'!K18,'Data Sheet'!K20:K24, -1*'Data Sheet'!K19) -> 19595 | L5: =SUM(Quarters!H5:K5) -> 42111 | M5: =M4-M6 -> 42111 | N5: =N4-N6 -> 41413.879
A6: Operating Profit | B6: =B4-B5 -> 0 | C6: =C4-C5 -> 0 | D6: =D4-D5 -> -92.45 | E6: =E4-E5 -> -2243.48 | F6: =F4-F5 -> -2304.7 | G6: =G4-G5 -> -467.1 | H6: =H4-H5 -> -1850.8 | I6: =I4-I5 -> -1211 | ... K6: =K4-K5 -> 648 | L6: =SUM(Quarters!H6:K6) -> 794 | M6: =M4*M24 -> 794 | N6: =N4*N24 -> 580.29508 | P6: 43 | Q6: 648
A7: Other Income | B7: ='Data Sheet'!B25 -> 0 | C7: ='Data Sheet'!C25 -> 0 | D7: ='Data Sheet'!D25 -> 21.03 | E7: ='Data Sheet'!E25 -> 1285.05 | F7: ='Data Sheet'!F25 -> 15.97 | G7: ='Data Sheet'!G25 -> -200.2 | H7: ='Data Sheet'!H25 -> 792.6 | I7: ='Data Sheet'!I25 -> 682 | ... K7: ='Data Sheet'!K25 -> 1066 | L7: =SUM(Quarters!H7:K7) -> 1422 | M7: 0 | N7: 0 | P7: 846 | Q7: 1066
A8: Depreciation | B8: ='Data Sheet'!B26 -> 0 | C8: ='Data Sheet'!C26 -> 0 | D8: ='Data Sheet'!D26 -> 29.15 | E8: ='Data Sheet'!E26 -> 43.12 | F8: ='Data Sheet'!F26 -> 84.24 | G8: ='Data Sheet'!G26 -> 137.7 | H8: ='Data Sheet'!H26 -> 150.3 | I8: ='Data Sheet'!I26 -> 437 | ... K8: ='Data Sheet'!K26 -> 863 | L8: =SUM(Quarters!H8:K8) -> 1416 | M8: =+$L8 -> 1416 | N8: =+$L8 -> 1416 | P8: =SUM(P6:P7) -> 889 | Q8: =SUM(Q6:Q7) -> 1714
A9: Interest | B9: ='Data Sheet'!B27 -> 0 | C9: ='Data Sheet'!C27 -> 0 | D9: ='Data Sheet'!D27 -> 6.35 | E9: ='Data Sheet'!E27 -> 8.69 | F9: ='Data Sheet'!F27 -> 12.64 | G9: ='Data Sheet'!G27 -> 10.1 | H9: ='Data Sheet'!H27 -> 12 | I9: ='Data Sheet'!I27 -> 49 | ... K9: ='Data Sheet'!K27 -> 154 | L9: =SUM(Quarters!H9:K9) -> 316 | M9: =+$L9 -> 316 | N9: =+$L9 -> 316
A10: Profit before tax | B10: ='Data Sheet'!B28 -> 0 | C10: ='Data Sheet'!C28 -> 0 | D10: ='Data Sheet'!D28 -> -106.92 | E10: ='Data Sheet'!E28 -> -1010.24 | F10: ='Data Sheet'!F28 -> -2385.61 | G10: ='Data Sheet'!G28 -> -815.1 | H10: ='Data Sheet'!H28 -> -1220.5 | I10: ='Data Sheet'!I28 -> -1015 | ... K10: ='Data Sheet'!K28 -> 697 | L10: =SUM(Quarters!H10:K10) -> 484 | M10: =M6+M7-SUM(M8:M9) -> -938 | N10: =N6+N7-SUM(N8:N9) -> -1151.7049
A11: Tax | B11: ='Data Sheet'!B29 -> 0 | C11: ='Data Sheet'!C29 -> 0 | D11: ='Data Sheet'!D29 -> 0 | E11: ='Data Sheet'!E29 -> 0 | F11: ='Data Sheet'!F29 -> 0 | G11: ='Data Sheet'!G29 -> 1.3 | H11: ='Data Sheet'!H29 -> 2 | I11: ='Data Sheet'!I29 -> -44 | ... K11: ='Data Sheet'!K29 -> 170 | L11: =SUM(Quarters!H11:K11) -> 253 | M11: =IF($L10>0,$L11/$L10,0) -> 0.52272727 | N11: =IF($L10>0,$L11/$L10,0) -> 0.52272727
A12: Net profit | B12: ='Data Sheet'!B30 -> 0 | C12: ='Data Sheet'!C30 -> 0 | D12: ='Data Sheet'!D30 -> -103.68 | E12: ='Data Sheet'!E30 -> -964.95 | F12: ='Data Sheet'!F30 -> -2367.16 | G12: ='Data Sheet'!G30 -> -812.8 | H12: ='Data Sheet'!H30 -> -1208.7 | I12: ='Data Sheet'!I30 -> -971 | ... K12: ='Data Sheet'!K30 -> 527 | L12: =SUM(Quarters!H12:K12) -> 231 | M12: =M10-M11*M10 -> -447.68182 | N12: =N10-N11*N10 -> -549.67735
A13: EPS | B13: =IF('Data Sheet'!B93>0,B12/'Data Sheet'!B93,0) -> 0 | C13: =IF('Data Sheet'!C93>0,C12/'Data Sheet'!C93,0) -> 0 | D13: =IF('Data Sheet'!D93>0,D12/'Data Sheet'!D93,0) -> -3456 | E13: =IF('Data Sheet'!E93>0,E12/'Data Sheet'!E93,0) -> -32165 | F13: =IF('Data Sheet'!F93>0,F12/'Data Sheet'!F93,0) -> -78905.333 | G13: =IF('Data Sheet'!G93>0,G12/'Data Sheet'!G93,0) -> -20320 | H13: =IF('Data Sheet'!H93>0,H12/'Data Sheet'!H93,0) -> -1.5354616 | I13: =IF('Data Sheet'!I93>0,I12/'Data Sheet'!I93,0) -> -1.1352078 | ... K13: =IF('Data Sheet'!K93>0,K12/'Data Sheet'!K93,0) -> 0.54609135 | L13: =IF('Data Sheet'!$B6>0,'Profit & Loss'!L12/'Data Sheet'!$B6,0) -> 0.23936954 | M13: =IF('Data Sheet'!$B6>0,'Profit & Loss'!M12/'Data Sheet'!$B6,0) -> -0.46390212 | N13: =IF('Data Sheet'!$B6>0,'Profit & Loss'!N12/'Data Sheet'!$B6,0) -> -0.56959313
A14: Price to earning | B14: =IF(B15>0,B15/B13,"") | C14: =IF(C15>0,C15/C13,"") | D14: =IF(D15>0,D15/D13,"") | E14: =IF(E15>0,E15/E13,"") | F14: =IF(F15>0,F15/F13,"") | G14: =IF(G15>0,G15/G13,"") | H14: =IF(H15>0,H15/H13,"") -> -53.599518 | I14: =IF(I15>0,I15/I13,"") -> -44.925695 | ... K14: =IF(K15>0,K15/K13,"") -> 369.35212 | L14: =IF(L13>0,L15/L13,0) -> 1125.6654 | M14: =M25 -> 1125.6654 | N14: =N25 -> 650.86391
A15: Price | B15: ='Data Sheet'!B90 -> 0 | C15: ='Data Sheet'!C90 -> 0 | D15: ='Data Sheet'!D90 -> 0 | E15: ='Data Sheet'!E90 -> 0 | F15: ='Data Sheet'!F90 -> 0 | G15: ='Data Sheet'!G90 -> 0 | H15: ='Data Sheet'!H90 -> 82.3 | I15: ='Data Sheet'!I90 -> 51 | ... K15: ='Data Sheet'!K90 -> 201.7 | L15: ='Data Sheet'!B8 -> 269.45 | M15: =M13*M14 -> -522.19855 | N15: =N13*N14 -> -370.72761
A17: RATIOS:
A18: Dividend Payout | B18: =IF('Data Sheet'!B30>0, 'Data Sheet'!B31/'Data Sheet'!B30, 0) -> 0 | C18: =IF('Data Sheet'!C30>0, 'Data Sheet'!C31/'Data Sheet'!C30, 0) -> 0 | D18: =IF('Data Sheet'!D30>0, 'Data Sheet'!D31/'Data Sheet'!D30, 0) -> 0 | E18: =IF('Data Sheet'!E30>0, 'Data Sheet'!E31/'Data Sheet'!E30, 0) -> 0 | F18: =IF('Data Sheet'!F30>0, 'Data Sheet'!F31/'Data Sheet'!F30, 0) -> 0 | G18: =IF('Data Sheet'!G30>0, 'Data Sheet'!G31/'Data Sheet'!G30, 0) -> 0 | H18: =IF('Data Sheet'!H30>0, 'Data Sheet'!H31/'Data Sheet'!H30, 0) -> 0 | I18: =IF('Data Sheet'!I30>0, 'Data Sheet'!I31/'Data Sheet'!I30, 0) -> 0 | ... K18: =IF('Data Sheet'!K30>0, 'Data Sheet'!K31/'Data Sheet'!K30, 0) -> 0
A19: OPM | B19: =IF(B6>0,B6/B4,0) -> 0 | C19: =IF(C6>0,C6/C4,0) -> 0 | D19: =IF(D6>0,D6/D4,0) -> 0 | E19: =IF(E6>0,E6/E4,0) -> 0 | F19: =IF(F6>0,F6/F4,0) -> 0 | G19: =IF(G6>0,G6/G4,0) -> 0 | H19: =IF(H6>0,H6/H4,0) -> 0 | I19: =IF(I6>0,I6/I4,0) -> 0 | ... L19: =IF(L6>0,L6/L4,0) -> 0.018506002
G22: TRENDS: | H22: 10 YEARS | I22: 7 YEARS | J22: 5 YEARS | K22: 3 YEARS | L22: RECENT | M22: BEST | N22: WORST
G23: Sales Growth | H23: =IF(B4=0,"",POWER($K4/B4,1/9)-1) | I23: =IF(D4=0,"",POWER($K4/D4,1/7)-1) -> 0.7138842 | J23: =IF(F4=0,"",POWER($K4/F4,1/5)-1) -> 0.5069613 | K23: =IF(H4=0,"",POWER($K4/H4, 1/3)-1) -> 0.69019724 | L23: =IF(ISERROR(MAX(IF(J4=0,"",(K4-J4)/J4),IF(K4=0,"",(L4-K4)/K4))),"",MAX(IF(J4=0,"",(K4-J4)/J4),IF(K4=0,"",(L4-K4)/K4))) -> 1.1194981 | M23: =MAX(K23:L23) -> 1.1194981 | N23: =MIN(H23:L23) -> 0.5069613
G24: OPM | H24: =IF(SUM(B4:$K$4)=0,"",SUMPRODUCT(B19:$K$19,B4:$K$4)/SUM(B4:$K$4)) -> 0.013818466 | I24: =IF(SUM(E4:$K$4)=0,"",SUMPRODUCT(E19:$K$19,E4:$K$4)/SUM(E4:$K$4)) -> 0.013948457 | J24: =IF(SUM(G4:$K$4)=0,"",SUMPRODUCT(G19:$K$19,G4:$K$4)/SUM(G4:$K$4)) -> 0.015146135 | K24: =IF(SUM(I4:$K$4)=0, "", SUMPRODUCT(I19:$K$19,I4:$K$4)/SUM(I4:$K$4)) -> 0.017522061 | L24: =L19 -> 0.018506002 | M24: =MAX(K24:L24) -> 0.018506002 | N24: =MIN(H24:L24) -> 0.013818466
G25: Price to Earning | H25: =IF(ISERROR(AVERAGEIF(B14:$L14,">0")),"",AVERAGEIF(B14:$L14,">0")) -> 650.86391 | I25: =IF(ISERROR(AVERAGEIF(E14:$L14,">0")),"",AVERAGEIF(E14:$L14,">0")) -> 650.86391 | J25: =IF(ISERROR(AVERAGEIF(G14:$L14,">0")),"",AVERAGEIF(G14:$L14,">0")) -> 650.86391 | K25: =IF(ISERROR(AVERAGEIF(I14:$L14,">0")),"",AVERAGEIF(I14:$L14,">0")) -> 650.86391 | L25: =L14 -> 1125.6654 | M25: =MAX(K25:L25) -> 1125.6654 | N25: =MIN(H25:L25) -> 650.86391

Sheet Final Dashboard
A1: Metrics (in Cr.) | B1: 45352 | C1: 45717 | E1: Mar 2026 (Est)
A2: Total Revenue | B2: 12114 | C2: 20243 | E2: =C2*1.4 -> 28340.2
A3: EBITDA | B3: 889 | C3: 1714 | E3: =E2/100*9.5 -> 2692.319
A4: Net Profit (PAT) | B4: 351 | C4: 527 | E4: =E2/100*2.7 -> 765.1854
A5: EPS (Earnings Per Share) | B5: 0.39796821 | C5: 0.54609135 | E5: =C5*1.3 -> 0.70991876
A7: EBITDA Margin % | B7: =B3/B2*100 -> 7.3386165 | C7: =C3/C2*100 -> 8.4671244 | E7: =E3/E2*100 -> 9.5
A8: NET PROFIT Margin % | B8: =B4/B2*100 -> 2.897474 | C8: =C4/C2*100 -> 2.6033691 | E8: =E4/E2*100 -> 2.7

Sheet Quarters
A1: ='Profit & Loss'!A1 -> ETERNAL LTD | E1: =UPDATE | J1: SCREENER.IN
A3: Narration | B3: ='Data Sheet'!B41 -> 45199 | C3: ='Data Sheet'!C41 -> 45291 | D3: ='Data Sheet'!D41 -> 45382 | E3: ='Data Sheet'!E41 -> 45473 | F3: ='Data Sheet'!F41 -> 45565 | G3: ='Data Sheet'!G41 -> 45657 | H3: ='Data Sheet'!H41 -> 45747 | I3: ='Data Sheet'!I41 -> 45838 | ... K3: ='Data Sheet'!K41 -> 46022
A4: Sales | B4: ='Data Sheet'!B42 -> 2848 | C4: ='Data Sheet'!C42 -> 3288 | D4: ='Data Sheet'!D42 -> 3562 | E4: ='Data Sheet'!E42 -> 4206 | F4: ='Data Sheet'!F42 -> 4799 | G4: ='Data Sheet'!G42 -> 5405 | H4: ='Data Sheet'!H42 -> 5833 | I4: ='Data Sheet'!I42 -> 7167 | ... K4: ='Data Sheet'!K42 -> 16315
A5: Expenses | B5: ='Data Sheet'!B43 -> 2895 | C5: ='Data Sheet'!C43 -> 3237 | D5: ='Data Sheet'!D43 -> 3476 | E5: ='Data Sheet'!E43 -> 4029 | F5: ='Data Sheet'!F43 -> 4573 | G5: ='Data Sheet'!G43 -> 5243 | H5: ='Data Sheet'!H43 -> 5761 | I5: ='Data Sheet'!I43 -> 7052 | ... K5: ='Data Sheet'!K43 -> 15947
A6: Operating Profit | B6: ='Data Sheet'!B50 -> -47 | C6: ='Data Sheet'!C50 -> 51 | D6: ='Data Sheet'!D50 -> 86 | E6: ='Data Sheet'!E50 -> 177 | F6: ='Data Sheet'!F50 -> 226 | G6: ='Data Sheet'!G50 -> 162 | H6: ='Data Sheet'!H50 -> 72 | I6: ='Data Sheet'!I50 -> 115 | ... K6: ='Data Sheet'!K50 -> 368
A7: Other Income | B7: ='Data Sheet'!B44 -> 212 | C7: ='Data Sheet'!C44 -> 219 | D7: ='Data Sheet'!D44 -> 235 | E7: ='Data Sheet'!E44 -> 236 | F7: ='Data Sheet'!F44 -> 221 | G7: ='Data Sheet'!G44 -> 252 | H7: ='Data Sheet'!H44 -> 368 | I7: ='Data Sheet'!I44 -> 354 | ... K7: ='Data Sheet'!K44 -> 348
A8: Depreciation | B8: ='Data Sheet'!B45 -> 128 | C8: ='Data Sheet'!C45 -> 128 | D8: ='Data Sheet'!D45 -> 140 | E8: ='Data Sheet'!E45 -> 149 | F8: ='Data Sheet'!F45 -> 180 | G8: ='Data Sheet'!G45 -> 247 | H8: ='Data Sheet'!H45 -> 287 | I8: ='Data Sheet'!I45 -> 314 | ... K8: ='Data Sheet'!K45 -> 439
A9: Interest | B9: ='Data Sheet'!B46 -> 16 | C9: ='Data Sheet'!C46 -> 18 | D9: ='Data Sheet'!D46 -> 20 | E9: ='Data Sheet'!E46 -> 25 | F9: ='Data Sheet'!F46 -> 30 | G9: ='Data Sheet'!G46 -> 43 | H9: ='Data Sheet'!H46 -> 56 | I9: ='Data Sheet'!I46 -> 67 | ... K9: ='Data Sheet'!K46 -> 107
A10: Profit before tax | B10: ='Data Sheet'!B47 -> 21 | C10: ='Data Sheet'!C47 -> 124 | D10: ='Data Sheet'!D47 -> 161 | E10: ='Data Sheet'!E47 -> 239 | F10: ='Data Sheet'!F47 -> 237 | G10: ='Data Sheet'!G47 -> 124 | H10: ='Data Sheet'!H47 -> 97 | I10: ='Data Sheet'!I47 -> 88 | ... K10: ='Data Sheet'!K47 -> 170
A11: Tax | B11: ='Data Sheet'!B48 -> -15 | C11: ='Data Sheet'!C48 -> -14 | D11: ='Data Sheet'!D48 -> -14 | E11: ='Data Sheet'!E48 -> -14 | F11: ='Data Sheet'!F48 -> 61 | G11: ='Data Sheet'!G48 -> 65 | H11: ='Data Sheet'!H48 -> 58 | I11: ='Data Sheet'!I48 -> 63 | ... K11: ='Data Sheet'!K48 -> 68
A12: Net profit | B12: ='Data Sheet'!B49 -> 36 | C12: ='Data Sheet'!C49 -> 138 | D12: ='Data Sheet'!D49 -> 175 | E12: ='Data Sheet'!E49 -> 253 | F12: ='Data Sheet'!F49 -> 176 | G12: ='Data Sheet'!G49 -> 59 | H12: ='Data Sheet'!H49 -> 39 | I12: ='Data Sheet'!I49 -> 25 | ... K12: ='Data Sheet'!K49 -> 102
A14: OPM | B14: =IF(B4>0,B6/B4,"") -> -0.016502809 | C14: =IF(C4>0,C6/C4,"") -> 0.015510949 | D14: =IF(D4>0,D6/D4,"") -> 0.024143739 | E14: =IF(E4>0,E6/E4,"") -> 0.042082739 | F14: =IF(F4>0,F6/F4,"") -> 0.047093144 | G14: =IF(G4>0,G6/G4,"") -> 0.029972248 | H14: =IF(H4>0,H6/H4,"") -> 0.012343562 | I14: =IF(I4>0,I6/I4,"") -> 0.016045765 | ... K14: =IF(K4>0,K6/K4,"") -> 0.02255593

Sheet Balance Sheet
A1: ='Profit & Loss'!A1 -> ETERNAL LTD | E1: =UPDATE | J1: SCREENER.IN
A3: Narration | B3: ='Data Sheet'!B56 -> 0 | C3: ='Data Sheet'!C56 -> 0 | D3: ='Data Sheet'!D56 -> 43190 | E3: ='Data Sheet'!E56 -> 43555 | F3: ='Data Sheet'!F56 -> 43921 | G3: ='Data Sheet'!G56 -> 44286 | H3: ='Data Sheet'!H56 -> 44651 | I3: ='Data Sheet'!I56 -> 45016 | ... K3: ='Data Sheet'!K56 -> 45747
A4: Equity Share Capital | B4: ='Data Sheet'!B57 -> 0 | C4: ='Data Sheet'!C57 -> 0 | D4: ='Data Sheet'!D57 -> 0.03 | E4: ='Data Sheet'!E57 -> 0.03 | F4: ='Data Sheet'!F57 -> 0.03 | G4: ='Data Sheet'!G57 -> 0 | H4: ='Data Sheet'!H57 -> 764.3 | I4: ='Data Sheet'!I57 -> 836 | ... K4: ='Data Sheet'!K57 -> 907
A5: Reserves | B5: ='Data Sheet'!B58 -> 0 | C5: ='Data Sheet'!C58 -> 0 | D5: ='Data Sheet'!D58 -> 1036.06 | E5: ='Data Sheet'!E58 -> 2355.61 | F5: ='Data Sheet'!F58 -> 457.35 | G5: ='Data Sheet'!G58 -> 7643.8 | H5: ='Data Sheet'!H58 -> 15741.2 | I5: ='Data Sheet'!I58 -> 18624 | ... K5: ='Data Sheet'!K58 -> 29410
A6: Borrowings | B6: ='Data Sheet'!B59 -> 0 | C6: ='Data Sheet'!C59 -> 0 | D6: ='Data Sheet'!D59 -> 186.23 | E6: ='Data Sheet'!E59 -> 347.94 | F6: ='Data Sheet'!F59 -> 325.58 | G6: ='Data Sheet'!G59 -> 527.4 | H6: ='Data Sheet'!H59 -> 70.3 | I6: ='Data Sheet'!I59 -> 507 | ... K6: ='Data Sheet'!K59 -> 2045
A7: Other Liabilities | B7: ='Data Sheet'!B60 -> 0 | C7: ='Data Sheet'!C60 -> 0 | D7: ='Data Sheet'!D60 -> 152.17 | E7: ='Data Sheet'!E60 -> 709.3 | F7: ='Data Sheet'!F60 -> 2117.43 | G7: ='Data Sheet'!G60 -> 532.3 | H7: ='Data Sheet'!H60 -> 751.2 | I7: ='Data Sheet'!I60 -> 1632 | ... K7: ='Data Sheet'!K60 -> 3261
A8: Total | B8: ='Data Sheet'!B61 -> 0 | C8: ='Data Sheet'!C61 -> 0 | D8: ='Data Sheet'!D61 -> 1374.49 | E8: ='Data Sheet'!E61 -> 3412.88 | F8: ='Data Sheet'!F61 -> 2900.39 | G8: ='Data Sheet'!G61 -> 8703.5 | H8: ='Data Sheet'!H61 -> 17327 | I8: ='Data Sheet'!I61 -> 21599 | ... K8: ='Data Sheet'!K61 -> 35623
A10: Net Block | B10: ='Data Sheet'!B62 -> 0 | C10: ='Data Sheet'!C62 -> 0 | D10: ='Data Sheet'!D62 -> 189.8 | E10: ='Data Sheet'!E62 -> 389.08 | F10: ='Data Sheet'!F62 -> 1590.55 | G10: ='Data Sheet'!G62 -> 1539 | H10: ='Data Sheet'!H62 -> 1404.3 | I10: ='Data Sheet'!I62 -> 6344 | ... K10: ='Data Sheet'!K62 -> 9532
A11: Capital Work in Progress | B11: ='Data Sheet'!B63 -> 0 | C11: ='Data Sheet'!C63 -> 0 | D11: ='Data Sheet'!D63 -> 1.29 | E11: ='Data Sheet'!E63 -> 0.74 | F11: ='Data Sheet'!F63 -> 0.96 | G11: ='Data Sheet'!G63 -> 0.1 | H11: ='Data Sheet'!H63 -> 0.6 | I11: ='Data Sheet'!I63 -> 7 | ... K11: ='Data Sheet'!K63 -> 51
A12: Investments | B12: ='Data Sheet'!B64 -> 0 | C12: ='Data Sheet'!C64 -> 0 | D12: ='Data Sheet'!D64 -> 829.23 | E12: ='Data Sheet'!E64 -> 2144.55 | F12: ='Data Sheet'!F64 -> 323.92 | G12: ='Data Sheet'!G64 -> 2205.2 | H12: ='Data Sheet'!H64 -> 4717.7 | I12: ='Data Sheet'!I64 -> 6765 | ... K12: ='Data Sheet'!K64 -> 13192
A13: Other Assets | B13: ='Data Sheet'!B65 -> 0 | C13: ='Data Sheet'!C65 -> 0 | D13: ='Data Sheet'!D65 -> 354.17 | E13: ='Data Sheet'!E65 -> 878.51 | F13: ='Data Sheet'!F65 -> 984.96 | G13: ='Data Sheet'!G65 -> 4959.2 | H13: ='Data Sheet'!H65 -> 11204.4 | I13: ='Data Sheet'!I65 -> 8483 | ... K13: ='Data Sheet'!K65 -> 12848
A14: Total | B14: ='Data Sheet'!B66 -> 0 | C14: ='Data Sheet'!C66 -> 0 | D14: ='Data Sheet'!D66 -> 1374.49 | E14: ='Data Sheet'!E66 -> 3412.88 | F14: ='Data Sheet'!F66 -> 2900.39 | G14: ='Data Sheet'!G66 -> 8703.5 | H14: ='Data Sheet'!H66 -> 17327 | I14: ='Data Sheet'!I66 -> 21599 | ... K14: ='Data Sheet'!K66 -> 35623
A16: Working Capital | B16: =B13-B7 -> 0 | C16: =C13-C7 -> 0 | D16: =D13-D7 -> 202 | E16: =E13-E7 -> 169.21 | F16: =F13-F7 -> -1132.47 | G16: =G13-G7 -> 4426.9 | H16: =H13-H7 -> 10453.2 | I16: =I13-I7 -> 6851 | ... K16: =K13-K7 -> 9587
A17: Debtors | B17: ='Data Sheet'!B67 -> 0 | C17: ='Data Sheet'!C67 -> 0 | D17: ='Data Sheet'!D67 -> 26.08 | E17: ='Data Sheet'!E67 -> 70.34 | F17: ='Data Sheet'!F67 -> 123.12 | G17: ='Data Sheet'!G67 -> 129.9 | H17: ='Data Sheet'!H67 -> 159.9 | I17: ='Data Sheet'!I67 -> 457 | ... K17: ='Data Sheet'!K67 -> 1946
A18: Inventory | B18: ='Data Sheet'!B68 -> 0 | C18: ='Data Sheet'!C68 -> 0 | D18: ='Data Sheet'!D68 -> 0 | E18: ='Data Sheet'!E68 -> 2.13 | F18: ='Data Sheet'!F68 -> 3.73 | G18: ='Data Sheet'!G68 -> 14.8 | H18: ='Data Sheet'!H68 -> 39.7 | I18: ='Data Sheet'!I68 -> 83 | ... K18: ='Data Sheet'!K68 -> 176
A20: Debtor Days | B20: =IF('Profit & Loss'!B4>0,'Balance Sheet'!B17/('Profit & Loss'!B4/365),0) -> 0 | C20: =IF('Profit & Loss'!C4>0,'Balance Sheet'!C17/('Profit & Loss'!C4/365),0) -> 0 | D20: =IF('Profit & Loss'!D4>0,'Balance Sheet'!D17/('Profit & Loss'!D4/365),0) -> 20.426591 | E20: =IF('Profit & Loss'!E4>0,'Balance Sheet'!E17/('Profit & Loss'!E4/365),0) -> 19.559878 | F20: =IF('Profit & Loss'!F4>0,'Balance Sheet'!F17/('Profit & Loss'!F4/365),0) -> 17.252701 | G20: =IF('Profit & Loss'!G4>0,'Balance Sheet'!G17/('Profit & Loss'!G4/365),0) -> 23.780469 | H20: =IF('Profit & Loss'!H4>0,'Balance Sheet'!H17/('Profit & Loss'!H4/365),0) -> 13.921262 | I20: =IF('Profit & Loss'!I4>0,'Balance Sheet'!I17/('Profit & Loss'!I4/365),0) -> 23.563356 | ... K20: =IF('Profit & Loss'!K4>0,'Balance Sheet'!K17/('Profit & Loss'!K4/365),0) -> 35.088179
A21: Inventory Turnover | B21: =IF('Balance Sheet'!B18>0,'Profit & Loss'!B4/'Balance Sheet'!B18,0) -> 0 | C21: =IF('Balance Sheet'!C18>0,'Profit & Loss'!C4/'Balance Sheet'!C18,0) -> 0 | D21: =IF('Balance Sheet'!D18>0,'Profit & Loss'!D4/'Balance Sheet'!D18,0) -> 0 | E21: =IF('Balance Sheet'!E18>0,'Profit & Loss'!E4/'Balance Sheet'!E18,0) -> 616.23944 | F21: =IF('Balance Sheet'!F18>0,'Profit & Loss'!F4/'Balance Sheet'!F18,0) -> 698.32172 | G21: =IF('Balance Sheet'!G18>0,'Profit & Loss'!G4/'Balance Sheet'!G18,0) -> 134.71622 | H21: =IF('Balance Sheet'!H18>0,'Profit & Loss'!H4/'Balance Sheet'!H18,0) -> 105.60202 | I21: =IF('Balance Sheet'!I18>0,'Profit & Loss'!I4/'Balance Sheet'!I18,0) -> 85.289157 | ... K21: =IF('Balance Sheet'!K18>0,'Profit & Loss'!K4/'Balance Sheet'!K18,0) -> 115.01705
A23: Return on Equity | B23: =IF(SUM('Balance Sheet'!B4:B5)>0,'Profit & Loss'!B12/SUM('Balance Sheet'!B4:B5),"") | C23: =IF(SUM('Balance Sheet'!C4:C5)>0,'Profit & Loss'!C12/SUM('Balance Sheet'!C4:C5),"") | D23: =IF(SUM('Balance Sheet'!D4:D5)>0,'Profit & Loss'!D12/SUM('Balance Sheet'!D4:D5),"") -> -0.10006853 | E23: =IF(SUM('Balance Sheet'!E4:E5)>0,'Profit & Loss'!E12/SUM('Balance Sheet'!E4:E5),"") -> -0.4096339 | F23: =IF(SUM('Balance Sheet'!F4:F5)>0,'Profit & Loss'!F12/SUM('Balance Sheet'!F4:F5),"") -> -5.1754777 | G23: =IF(SUM('Balance Sheet'!G4:G5)>0,'Profit & Loss'!G12/SUM('Balance Sheet'!G4:G5),"") -> -0.10633455 | H23: =IF(SUM('Balance Sheet'!H4:H5)>0,'Profit & Loss'!H12/SUM('Balance Sheet'!H4:H5),"") -> -0.073230135 | I23: =IF(SUM('Balance Sheet'!I4:I5)>0,'Profit & Loss'!I12/SUM('Balance Sheet'!I4:I5),"") -> -0.049897225 | ... K23: =IF(SUM('Balance Sheet'!K4:K5)>0,'Profit & Loss'!K12/SUM('Balance Sheet'!K4:K5),"") -> 0.017382986
A24: Return on Capital Emp | C24: =IF((B4+B5+B6+C4+C5+C6)>0,('Profit & Loss'!C10+'Profit & Loss'!C9)*2/(B4+B5+B6+C4+C5+C6),"") | D24: =IF((C4+C5+C6+D4+D5+D6)>0,('Profit & Loss'!D10+'Profit & Loss'!D9)*2/(C4+C5+C6+D4+D5+D6),"") -> -0.16455593 | E24: =IF((D4+D5+D6+E4+E5+E6)>0,('Profit & Loss'!E10+'Profit & Loss'!E9)*2/(D4+D5+D6+E4+E5+E6),"") -> -0.51022695 | F24: =IF((E4+E5+E6+F4+F5+F6)>0,('Profit & Loss'!F10+'Profit & Loss'!F9)*2/(E4+E5+E6+F4+F5+F6),"") -> -1.3612177 | G24: =IF((F4+F5+F6+G4+G5+G6)>0,('Profit & Loss'!G10+'Profit & Loss'!G9)*2/(F4+F5+F6+G4+G5+G6),"") -> -0.17980469 | H24: =IF((G4+G5+G6+H4+H5+H6)>0,('Profit & Loss'!H10+'Profit & Loss'!H9)*2/(G4+G5+G6+H4+H5+H6),"") -> -0.097668404 | I24: =IF((H4+H5+H6+I4+I5+I6)>0,('Profit & Loss'!I10+'Profit & Loss'!I9)*2/(H4+H5+H6+I4+I5+I6),"") -> -0.052869512 | J24: =IF((I4+I5+I6+J4+J5+J6)>0,('Profit & Loss'!J10+'Profit & Loss'!J9)*2/(I4+I5+I6+J4+J5+J6),"") -> 0.017651779 | K24: =IF((J4+J5+J6+K4+K5+K6)>0,('Profit & Loss'!K10+'Profit & Loss'!K9)*2/(J4+J5+J6+K4+K5+K6),"") -> 0.031798819

Sheet Cash Flow
A1: ='Balance Sheet'!A1 -> ETERNAL LTD | E1: =UPDATE | J1: SCREENER.IN
A3: Narration | B3: ='Data Sheet'!B81 -> 0 | C3: ='Data Sheet'!C81 -> 0 | D3: ='Data Sheet'!D81 -> 43190 | E3: ='Data Sheet'!E81 -> 43555 | F3: ='Data Sheet'!F81 -> 43921 | G3: ='Data Sheet'!G81 -> 44286 | H3: ='Data Sheet'!H81 -> 44651 | I3: ='Data Sheet'!I81 -> 45016 | ... K3: ='Data Sheet'!K81 -> 45747
A4: Cash from Operating Activity | B4: ='Data Sheet'!B82 -> 0 | C4: ='Data Sheet'!C82 -> 0 | D4: ='Data Sheet'!D82 -> 0 | E4: ='Data Sheet'!E82 -> 0 | F4: ='Data Sheet'!F82 -> -2143.63 | G4: ='Data Sheet'!G82 -> -1017.9 | H4: ='Data Sheet'!H82 -> -693 | I4: ='Data Sheet'!I82 -> -844 | ... K4: ='Data Sheet'!K82 -> 308
A5: Cash from Investing Activity | B5: ='Data Sheet'!B83 -> 0 | C5: ='Data Sheet'!C83 -> 0 | D5: ='Data Sheet'!D83 -> 0 | E5: ='Data Sheet'!E83 -> 0 | F5: ='Data Sheet'!F83 -> 1739.51 | G5: ='Data Sheet'!G83 -> -5244.6 | H5: ='Data Sheet'!H83 -> -7971 | I5: ='Data Sheet'!I83 -> 797 | ... K5: ='Data Sheet'!K83 -> -7993
A6: Cash from Financing Activity | B6: ='Data Sheet'!B84 -> 0 | C6: ='Data Sheet'!C84 -> 0 | D6: ='Data Sheet'!D84 -> 0 | E6: ='Data Sheet'!E84 -> 0 | F6: ='Data Sheet'!F84 -> 358.91 | G6: ='Data Sheet'!G84 -> 6401.9 | H6: ='Data Sheet'!H84 -> 8749.8 | I6: ='Data Sheet'!I84 -> -127 | ... K6: ='Data Sheet'!K84 -> 8042
A7: Net Cash Flow | B7: ='Data Sheet'!B85 -> 0 | C7: ='Data Sheet'!C85 -> 0 | D7: ='Data Sheet'!D85 -> 0 | E7: ='Data Sheet'!E85 -> 0 | F7: ='Data Sheet'!F85 -> -45.22 | G7: ='Data Sheet'!G85 -> 139.4 | H7: ='Data Sheet'!H85 -> 85.8 | I7: ='Data Sheet'!I85 -> -174 | ... K7: ='Data Sheet'!K85 -> 357

Sheet Customization
A1: How to use it?
A3: You can customize this workbook as you want.
B4: You can add custom formating, add conditional formating, add your own formulas… do ANYTHING.
B5: Please don't edit the "Data Sheet" only.
A7: After customization, you can upload this back on Screener.
B8: Upload on: | C8: https://www.screener.in/excel/
A10: Download your customized workbooks now onwards.
B11: Now whenever you will "Export to excel" from Screener, it will export your customized file.
A14: TESTING:
B15: This is a testing feature currently.
B16: You can report any formula errors on the worksheet at: support@screener.in

Sheet Data Sheet
A1: COMPANY NAME | B1: ETERNAL LTD | E1: =IF(B2<>B3, "A NEW VERSION OF THE WORKSHEET IS AVAILABLE", "")
A2: LATEST VERSION | B2: 2.1 | E2: PLEASE DO NOT MAKE ANY CHANGES TO THIS SHEET
A3: CURRENT VERSION | B3: 2.1
A5: META
A6: Number of shares | B6: =IF(B9>0, B9/B8, 0) -> 965.03507
A7: Face Value | B7: 1
A8: Current Price | B8: 269.45
A9: Market Capitalization | B9: 260028.7
A15: PROFIT & LOSS
A16: Report Date | D16: 43190 | E16: 43555 | F16: 43921 | G16: 44286 | H16: 44651 | I16: 45016 | J16: 45382 | K16: 45747
A17: Sales | D17: 466.02 | E17: 1312.59 | F17: 2604.74 | G17: 1993.8 | H17: 4192.4 | I17: 7079 | J17: 12114 | K17: 20243
A18: Raw Material Cost | E18: 18.72 | F18: 110.52 | G18: 202.9 | H18: 552.4 | I18: 1438 | J18: 2887 | K18: 5653
A19: Change in Inventory | E19: 2.13 | F19: 1.6 | G19: 11 | H19: 27.8 | I19: 43 | J19: 5 | K19: 88
A20: Power and Fuel | D20: 2.41 | E20: 3.17 | F20: 6.29 | G20: 1.9 | H20: 4 | I20: 23 | J20: 51 | K20: 143
A21: Other Mfr. Exp | D21: 49.81 | E21: 1339.7 | F21: 2108.91 | G21: 74.5 | H21: 183.3 | I21: 384 | J21: 521 | K21: 968
A22: Employee Cost | D22: 290.49 | E22: 600.79 | F22: 798.88 | G22: 740.8 | H22: 1633.1 | I22: 1465 | J22: 1659 | K22: 2558
A23: Selling and admin | D23: 182.17 | E23: 1514.3 | F23: 1756.34 | G23: 1435 | H23: 3654.4 | I23: 4961 | J23: 6882 | K23: 10275
A24: Other Expenses | D24: 33.59 | E24: 81.52 | F24: 130.1 | G24: 16.8 | H24: 43.8 | I24: 62 | J24: 76 | K24: 86
A25: Other Income | D25: 21.03 | E25: 1285.05 | F25: 15.97 | G25: -200.2 | H25: 792.6 | I25: 682 | J25: 846 | K25: 1066
A26: Depreciation | D26: 29.15 | E26: 43.12 | F26: 84.24 | G26: 137.7 | H26: 150.3 | I26: 437 | J26: 526 | K26: 863
A27: Interest | D27: 6.35 | E27: 8.69 | F27: 12.64 | G27: 10.1 | H27: 12 | I27: 49 | J27: 72 | K27: 154
A28: Profit before tax | D28: -106.92 | E28: -1010.24 | F28: -2385.61 | G28: -815.1 | H28: -1220.5 | I28: -1015 | J28: 291 | K28: 697
A29: Tax | G29: 1.3 | H29: 2 | I29: -44 | J29: -60 | K29: 170
A30: Net profit | D30: -103.68 | E30: -964.95 | F30: -2367.16 | G30: -812.8 | H30: -1208.7 | I30: -971 | J30: 351 | K30: 527
A31: Dividend Amount
A40: Quarters
A41: Report Date | B41: 45199 | C41: 45291 | D41: 45382 | E41: 45473 | F41: 45565 | G41: 45657 | H41: 45747 | I41: 45838 | J41: 45930 | K41: 46022
A42: Sales | B42: 2848 | C42: 3288 | D42: 3562 | E42: 4206 | F42: 4799 | G42: 5405 | H42: 5833 | I42: 7167 | J42: 13590 | K42: 16315
A43: Expenses | B43: 2895 | C43: 3237 | D43: 3476 | E43: 4029 | F43: 4573 | G43: 5243 | H43: 5761 | I43: 7052 | J43: 13351 | K43: 15947
A44: Other Income | B44: 212 | C44: 219 | D44: 235 | E44: 236 | F44: 221 | G44: 252 | H44: 368 | I44: 354 | J44: 352 | K44: 348
A45: Depreciation | B45: 128 | C45: 128 | D45: 140 | E45: 149 | F45: 180 | G45: 247 | H45: 287 | I45: 314 | J45: 376 | K45: 439
A46: Interest | B46: 16 | C46: 18 | D46: 20 | E46: 25 | F46: 30 | G46: 43 | H46: 56 | I46: 67 | J46: 86 | K46: 107
A47: Profit before tax | B47: 21 | C47: 124 | D47: 161 | E47: 239 | F47: 237 | G47: 124 | H47: 97 | I47: 88 | J47: 129 | K47: 170
A48: Tax | B48: -15 | C48: -14 | D48: -14 | E48: -14 | F48: 61 | G48: 65 | H48: 58 | I48: 63 | J48: 64 | K48: 68
A49: Net profit | B49: 36 | C49: 138 | D49: 175 | E49: 253 | F49: 176 | G49: 59 | H49: 39 | I49: 25 | J49: 65 | K49: 102
A50: Operating Profit | B50: -47 | C50: 51 | D50: 86 | E50: 177 | F50: 226 | G50: 162 | H50: 72 | I50: 115 | J50: 239 | K50: 368
A55: BALANCE SHEET
A56: Report Date | D56: 43190 | E56: 43555 | F56: 43921 | G56: 44286 | H56: 44651 | I56: 45016 | J56: 45382 | K56: 45747
A57: Equity Share Capital | D57: 0.03 | E57: 0.03 | F57: 0.03 | H57: 764.3 | I57: 836 | J57: 868 | K57: 907
A58: Reserves | D58: 1036.06 | E58: 2355.61 | F58: 457.35 | G58: 7643.8 | H58: 15741.2 | I58: 18624 | J58: 19545 | K58: 29410
...
